Workbook

Sheet Table001 (Page 1-11)
I2: Estimated Traffic Characteristics | M2: Peak Hour / Peak Season | U2: Historical Crash Data 2018 - 2022 | W2: Multimodal Factors
E3: Roadway Characteristics | K3: 100th Highest Hour | M3: Based on v/c this is PkHrPkDir Vol | P3: LOS Standard | W3: Transit | X3: Sidewalk | Z3: Bicycle Facility
A4: Link | B4: Road Segment | C4: From | D4: To | E4: Laneage Lane Type | F4: Capacity Group | G4: Segment Length | H4: Functional Classification | I4: 2023 Annual Avg. Daily Traffic | J4: AADT Growth Rate (%) | K4: D-Factor | L4: K-Factor | M4: Two-Hour Average Volume | N4: Level of Service | O4: Direc-tional Capacity | P4: Multi-Modal | Q4: High-Way | R4: Volume to Capacity Ratio | S4: Volume-to-Capacity Ratio in Five Years | T4: Projected LOS in Five Years | U4: Total Crashes | V4: Crash Rate | W4: Presence | X4: Presence | Y4: Coverage | Z4: Presence | AA4: Coverage
A5: 8301N | B5: ADAMS ROAD/MOHAWK RD | C5: BOLENDER ROAD | D5: CR 559 | E5: 2U | F5: L02 | G5: 1.8 | H5: URBAN COLLECTOR | I5: 3800 | J5: 2 | K5: 0.49 | L5: 0.09 | M5: 168 | N5: C | O5: 790 | P5: TRANSITIONING | Q5: D | R5: 0.21 | S5: 0.23 | T5: C | U5: 2 | V5: 0.158 | W5: NO | X5: PARTIAL | Y5: 0.59 | Z5: NONE | AA5: 0
A6: 8301S | B6: ADAMS ROAD/MOHAWK RD | C6: BOLENDER ROAD | D6: CR 559 | E6: 2U | F6: L02 | G6: 1.8 | H6: URBAN COLLECTOR | I6: 3800 | J6: 2 | K6: 0.51 | L6: 0.09 | M6: 174 | N6: C | O6: 790 | P6: TRANSITIONING | Q6: D | R6: 0.22 | S6: 0.24 | T6: C | U6: 2 | V6: 0.158 | W6: NO | X6: PARTIAL | Y6: 0.59 | Z6: NONE | AA6: 0
A7: 8302E | B7: ALAMO DRIVE | C7: OLD HIGHWAY 37 | D7: SR 37 | E7: 2U | F7: L02 | G7: 0.2 | H7: URBAN COLLECTOR | I7: 8500 | J7: 2 | K7: 0.49 | L7: 0.075 | M7: 297 | N7: C | O7: 790 | P7: TCCO | Q7: E | R7: 0.38 | S7: 0.41 | T7: C | U7: 40 | V7: 10.374 | W7: NO | X7: PARTIAL | Y7: 1 | Z7: NONE | AA7: 0
A8: 8302W | B8: ALAMO DRIVE | C8: OLD HIGHWAY 37 | D8: SR 37 | E8: 2U | F8: L02 | G8: 0.2 | H8: URBAN COLLECTOR | I8: 8500 | J8: 2 | K8: 0.51 | L8: 0.075 | M8: 309 | N8: C | O8: 790 | P8: TCCO | Q8: E | R8: 0.39 | S8: 0.43 | T8: C | U8: 40 | V8: 10.374 | W8: NO | X8: PARTIAL | Y8: 1 | Z8: NONE | AA8: 0
A9: 8303E | B9: ALAMO DRIVE | C9: SR 563 (HARDEN BLVD S) | D9: OLD HIGHWAY 37 | E9: 2U | F9: L02 | G9: 0.8 | H9: URBAN COLLECTOR | I9: 5000 | J9: 2 | K9: 0.49 | L9: 0.09 | M9: 221 | N9: C | O9: 790 | P9: TSDA | Q9: D | R9: 0.28 | S9: 0.31 | T9: C | U9: 15 | V9: 2.18 | W9: NO | X9: PARTIAL | Y9: 0.94 | Z9: NONE | AA9: 0
A10: 8303W | B10: ALAMO DRIVE | C10: SR 563 (HARDEN BLVD S) | D10: OLD HIGHWAY 37 | E10: 2U | F10: L02 | G10: 0.8 | H10: URBAN COLLECTOR | I10: 5000 | J10: 2 | K10: 0.51 | L10: 0.09 | M10: 230 | N10: C | O10: 790 | P10: TSDA | Q10: D | R10: 0.29 | S10: 0.32 | T10: C | U10: 15 | V10: 2.18 | W10: NO | X10: PARTIAL | Y10: 0.94 | Z10: NONE | AA10: 0
A11: 4010E | B11: ALTURAS-BABSON PARK CUTOFF RD | C11: CR 559 | D11: US 27 | E11: 2U | F11: H02 | G11: 12.1 | H11: RURAL MAJOR COLLECTOR | I11: 1900 | J11: 2 | K11: 0.49 | L11: 0.09 | M11: 84 | N11: B | O11: 450 | P11: OTHER | Q11: C | R11: 0.19 | S11: 0.2 | T11: B | U11: 0 | V11: 0 | W11: NO | X11: NONE | Y11: 0 | Z11: NONE | AA11: 0
A12: 4010W | B12: ALTURAS-BABSON PARK CUTOFF RD | C12: CR 559 | D12: US 27 | E12: 2U | F12: H02 | G12: 12.1 | H12: RURAL MAJOR COLLECTOR | I12: 1900 | J12: 2 | K12: 0.51 | L12: 0.09 | M12: 87 | N12: B | O12: 450 | P12: OTHER | Q12: C | R12: 0.19 | S12: 0.21 | T12: B | U12: 0 | V12: 0 | W12: NO | X12: NONE | Y12: 0 | Z12: NONE | AA12: 0
A13: 4011N | B13: AMERICAN SUPERIOR BLVD/HOOVER RD/SHELL RD/LK ELOISE DR W | C13: CR 655 (SNIVELY AVE) | D13: AVE Z SE | E13: 2U | F13: L02 | G13: 1.7 | H13: URBAN COLLECTOR | I13: 3300 | J13: 2 | K13: 0.49 | L13: 0.09 | M13: 146 | N13: C | O13: 790 | P13: TSDA | Q13: D | R13: 0.18 | S13: 0.2 | T13: C | U13: 0 | V13: 0 | W13: NO | X13: NONE | Y13: 0 | Z13: PARTIAL | AA13: 0.03
A14: 4011S | B14: AMERICAN SUPERIOR BLVD/HOOVER RD/SHELL RD/LK ELOISE DR W | C14: CR 655 (SNIVELY AVE) | D14: AVE Z SE | E14: 2U | F14: L02 | G14: 1.7 | H14: URBAN COLLECTOR | I14: 3300 | J14: 2 | K14: 0.51 | L14: 0.09 | M14: 151 | N14: C | O14: 790 | P14: TSDA | Q14: D | R14: 0.19 | S14: 0.21 | T14: C | U14: 0 | V14: 0 | W14: NO | X14: NONE | Y14: 0 | Z14: PARTIAL | AA14: 0.03
A15: 4012E | B15: ARIANA ST | C15: WABASH AVE S | D15: SR 563 (HARDEN BLVD) | E15: 2U | F15: L02 | G15: 1 | H15: URBAN COLLECTOR | I15: 10900 | J15: 2 | K15: 0.49 | L15: 0.075 | M15: 381 | N15: C | O15: 790 | P15: MULTI-MODAL | Q15: D | R15: 0.48 | S15: 0.53 | T15: C | U15: 39 | V15: 1.927 | W15: YES | X15: PARTIAL | Y15: 0.59 | Z15: NONE | AA15: 0
A16: 4012W | B16: ARIANA ST | C16: WABASH AVE S | D16: SR 563 (HARDEN BLVD) | E16: 2U | F16: L02 | G16: 1 | H16: URBAN COLLECTOR | I16: 10900 | J16: 2 | K16: 0.51 | L16: 0.075 | M16: 396 | N16: C | O16: 790 | P16: MULTI-MODAL | Q16: D | R16: 0.5 | S16: 0.55 | T16: C | U16: 39 | V16: 1.927 | W16: YES | X16: PARTIAL | Y16: 0.59 | Z16: NONE | AA16: 0
... A58: 4016W | B58: BOLENDER RD | C58: CR 559 (POLK CITY ROAD) | D58: LAKE ALFRED RD | E58: 2U | F58: L02 | G58: 1.6 | H58: URBAN COLLECTOR | I58: 4600 | J58: 2 | K58: 0.51 | L58: 0.09 | M58: 211 | N58: C | O58: 790 | P58: TRANSITIONING | Q58: D | R58: 0.27 | S58: 0.29 | T58: C | U58: 7 | V58: 0.519 | W58: NO | X58: PARTIAL | Y58: 0.33 | Z58: NONE | AA58: 0
A59: 8450E | B59: BRADDOCK ROAD | C59: SR 570 (POLK PARKWAY) | D59: SR 655 (BERKLEY RD) | E59: 2U | F59: C02 | G59: 0.8 | H59: URBAN COLLECTOR | I59: 0 | J59: 2 | K59: 0.49 | L59: 0.09 | M59: 0 | N59: C | O59: 750 | P59: TRANSITIONING | Q59: D | R59: 0 | S59: 0 | T59: C | U59: 0 | V59: #DIV/0! | W59: NO | X59: NONE | Y59: 0 | Z59: NONE | AA59: 0
A60: 8450W | B60: BRADDOCK ROAD | C60: SR 570 (POLK PARKWAY) | D60: SR 655 (BERKLEY RD) | E60: 2U | F60: C02 | G60: 0.8 | H60: URBAN COLLECTOR | I60: 0 | J60: 2 | K60: 0.51 | L60: 0.09 | M60: 0 | N60: C | O60: 750 | P60: TRANSITIONING | Q60: D | R60: 0 | S60: 0 | T60: C | U60: 0 | V60: #DIV/0! | W60: NO | X60: NONE | Y60: 0 | Z60: NONE | AA60: 0
A61: 4018E | B61: BRIDGERS AVE | C61: US 92 | D61: US 92 (MAGNOLIA AVENUE) | E61: 2U | F61: L02 | G61: 2 | H61: URBAN COLLECTOR | I61: 3800 | J61: 2 | K61: 0.49 | L61: 0.075 | M61: 133 | N61: C | O61: 790 | P61: TCCO | Q61: E | R61: 0.17 | S61: 0.18 | T61: C | U61: 35 | V61: 2.471 | W61: YES | X61: PARTIAL | Y61: 1.04 | Z61: NONE | AA61: 0
A62: 4018W | B62: BRIDGERS AVE | C62: US 92 | D62: US 92 (MAGNOLIA AVENUE) | E62: 2U | F62: L02 | G62: 2 | H62: URBAN COLLECTOR | I62: 3800 | J62: 2 | K62: 0.51 | L62: 0.075 | M62: 138 | N62: C | O62: 790 | P62: TCCO | Q62: E | R62: 0.17 | S62: 0.19 | T62: C | U62: 35 | V62: 2.471 | W62: YES | X62: PARTIAL | Y62: 1.04 | Z62: NONE | AA62: 0
A63: 5403N | B63: BROADWAY AVE N | C63: MAIN ST | D63: SR 60 (VAN FLEET DRIVE) | E63: 4D | F63: C02 | G63: 0.5 | H63: URBAN COLLECTOR | I63: 14600 | J63: 2 | K63: 0.49 | L63: 0.075 | M63: 510 | N63: C | O63: 1790 | P63: TCCO | Q63: E | R63: 0.28 | S63: 0.31 | T63: C | U63: 86 | V63: 6.156 | W63: YES | X63: FULL | Y63: 1.7 | Z63: NONE | AA63: 0
A64: 5403S | B64: BROADWAY AVE N | C64: MAIN ST | D64: SR 60 (VAN FLEET DRIVE) | E64: 4D | F64: C02 | G64: 0.5 | H64: URBAN COLLECTOR | I64: 14600 | J64: 2 | K64: 0.51 | L64: 0.075 | M64: 531 | N64: C | O64: 1790 | P64: TCCO | Q64: E | R64: 0.3 | S64: 0.33 | T64: C | U64: 86 | V64: 6.156 | W64: YES | X64: FULL | Y64: 1.7 | Z64: NONE | AA64: 0
A65: 8435N | B65: BROADWAY AVENUE SOUTH | C65: STUART AVE | D65: MAIN STREET | E65: 2U | F65: C02 | G65: 0.7 | H65: URBAN COLLECTOR | I65: 8600 | J65: 2 | K65: 0.49 | L65: 0.075 | M65: 300 | N65: C | O65: 800 | P65: TCCO | Q65: E | R65: 0.38 | S65: 0.41 | T65: C | U65: 41 | V65: 3.622 | W65: NO | X65: FULL | Y65: 1.85 | Z65: NONE | AA65: 0
A66: 8435S | B66: BROADWAY AVENUE SOUTH | C66: STUART AVE | D66: MAIN STREET | E66: 2U | F66: C02 | G66: 0.7 | H66: URBAN COLLECTOR | I66: 8600 | J66: 2 | K66: 0.51 | L66: 0.075 | M66: 313 | N66: C | O66: 800 | P66: TCCO | Q66: E | R66: 0.39 | S66: 0.43 | T66: C | U66: 41 | V66: 3.622 | W66: NO | X66: FULL | Y66: 1.85 | Z66: NONE | AA66: 0
A67: 8436N | B67: BROADWAY AVENUE SOUTH/SHUMATE DR | C67: CLOWER STREET | D67: STUART AVE | E67: 4U | F67: C02 | G67: 0.5 | H67: URBAN COLLECTOR | I67: 5000 | J67: 2 | K67: 0.51 | L67: 0.075 | M67: 182 | N67: C | O67: 1620 | P67: TCCO | Q67: E | R67: 0.11 | S67: 0.12 | T67: C | U67: 17 | V67: 3.695 | W67: NO | X67: PARTIAL | Y67: 1.26 | Z67: NONE | AA67: 0
A68: 8436S | B68: BROADWAY AVENUE SOUTH/SHUMATE DR | C68: CLOWER STREET | D68: STUART AVE | E68: 4U | F68: C02 | G68: 0.5 | H68: URBAN COLLECTOR | I68: 5000 | J68: 2 | K68: 0.49 | L68: 0.075 | M68: 175 | N68: C | O68: 1620 | P68: TCCO | Q68: E | R68: 0.11 | S68: 0.12 | T68: C | U68: 17 | V68: 3.695 | W68: NO | X68: PARTIAL | Y68: 1.26 | Z68: NONE | AA68: 0
A69: 4020N | B69: BUCKEYE LOOP RD | C69: SR 542 (DUNDEE RD) | D69: AVE T NE | E69: 2U | F69: L02 | G69: 1.5 | H69: URBAN COLLECTOR | I69: 9400 | J69: 2 | K69: 0.51 | L69: 0.09 | M69: 431 | N69: C | O69: 790 | P69: TRANSITIONING | Q69: D | R69: 0.55 | S69: 0.6 | T69: C | U69: 2 | V69: 0.08 | W69: NO | X69: PARTIAL | Y69: 0.3 | Z69: PARTIAL | AA69: 0.25
A70: 4020S | B70: BUCKEYE LOOP RD | C70: SR 542 (DUNDEE RD) | D70: AVE T NE | E70: 2U | F70: L02 | G70: 1.5 | H70: URBAN COLLECTOR | I70: 9400 | J70: 2 | K70: 0.49 | L70: 0.09 | M70: 415 | N70: C | O70: 790 | P70: TRANSITIONING | Q70: D | R70: 0.52 | S70: 0.58 | T70: C | U70: 2 | V70: 0.08 | W70: NO | X70: PARTIAL | Y70: 0.3 | Z70: PARTIAL | AA70: 0.25
A71: 4021E | B71: BUCKEYE RD | C71: 11TH ST NE | D71: BUCKEYE LOOP RD | E71: 2U | F71: L02 | G71: 1.2 | H71: URBAN COLLECTOR | I71: 3800 | J71: 2 | K71: 0.51 | L71: 0.09 | M71: 174 | N71: C | O71: 790 | P71: TRANSITIONING | Q71: D | R71: 0.22 | S71: 0.24 | T71: C | U71: 4 | V71: 0.497 | W71: NO | X71: PARTIAL | Y71: 0.54 | Z71: NONE | AA71: 0
A72: 4021W | B72: BUCKEYE RD | C72: 11TH ST NE | D72: BUCKEYE LOOP RD | E72: 2U | F72: L02 | G72: 1.2 | H72: URBAN COLLECTOR | I72: 3800 | J72: 2 | K72: 0.49 | L72: 0.09 | M72: 168 | N72: C | O72: 790 | P72: TRANSITIONING | Q72: D | R72: 0.21 | S72: 0.23 | T72: C | U72: 4 | V72: 0.497 | W72: NO | X72: PARTIAL | Y72: 0.54 | Z72: NONE | AA72: 0
... A374: 8107W | B374: GIBSONIA-GALLOWAY ROAD | C374: CR 35A (KATHLEEN ROAD) | D374: US 98 | E374: 2U | F374: L02 | G374: 3.3 | H374: URBAN COLLECTOR | I374: 7100 | J374: 2 | K374: 0.51 | L374: 0.09 | M374: 326 | N374: C | O374: 790 | P374: TRANSITIONING | Q374: D | R374: 0.41 | S374: 0.45 | T374: C | U374: 33 | V374: 0.764 | W374: NO | X374: PARTIAL | Y374: 0.07 | Z374: NONE | AA374: 0
A375: 8449E | B375: GLENDALE STREET | C375: NEW JERSEY ROAD | D375: LAKELAND HIGHLANDS ROAD | E375: 2U | F375: C02 | G375: 0.5 | H375: URBAN COLLECTOR | I375: 0 | J375: 2 | K375: 0.51 | L375: 0.075 | M375: 0 | N375: C | O375: 800 | P375: TCCO | Q375: E | R375: 0 | S375: 0 | T375: C | U375: 9 | V375: #DIV/0! | W375: NO | X375: NONE | Y375: 0 | Z375: NONE | AA375: 0
A376: 8449W | B376: GLENDALE STREET | C376: NEW JERSEY ROAD | D376: LAKELAND HIGHLANDS ROAD | E376: 2U | F376: C02 | G376: 0.5 | H376: URBAN COLLECTOR | I376: 0 | J376: 2 | K376: 0.49 | L376: 0.075 | M376: 0 | N376: C | O376: 800 | P376: TCCO | Q376: E | R376: 0 | S376: 0 | T376: C | U376: 9 | V376: #DIV/0! | W376: NO | X376: NONE | Y376: 0 | Z376: NONE | AA376: 0
A377: 8434N | B377: GOLFVIEW CUTOFF/FRIEDLANDER/LEWIS GRIFFIN ROAD | C377: STATE ROAD 17 (SCENIC HIGHWAY) | D377: STATE ROAD 60 | E377: 2U | F377: H02 | G377: 4.7 | H377: URBAN COLLECTOR | I377: 2600 | J377: 2 | K377: 0.49 | L377: 0.09 | M377: 115 | N377: B | O377: 730 | P377: TRANSITIONING | Q377: D | R377: 0.16 | S377: 0.17 | T377: B | U377: 0 | V377: 0 | W377: YES | X377: NONE | Y377: 0 | Z377: NONE | AA377: 0
A378: 8434S | B378: GOLFVIEW CUTOFF/FRIEDLANDER/LEWIS GRIFFIN ROAD | C378: STATE ROAD 17 (SCENIC HIGHWAY) | D378: STATE ROAD 60 | E378: 2U | F378: H02 | G378: 4.7 | H378: URBAN COLLECTOR | I378: 2600 | J378: 2 | K378: 0.51 | L378: 0.09 | M378: 119 | N378: B | O378: 730 | P378: TRANSITIONING | Q378: D | R378: 0.16 | S378: 0.18 | T378: B | U378: 0 | V378: 0 | W378: YES | X378: NONE | Y378: 0 | Z378: NONE | AA378: 0
A379: 8313E | B379: GRACE AVENUE E/HORNET DRIVE | C379: SR 17/TENTH STREET | D379: 30TH STREET | E379: 2U | F379: L02 | G379: 1.1 | H379: URBAN COLLECTOR | I379: 3400 | J379: 2 | K379: 0.49 | L379: 0.075 | M379: 119 | N379: C | O379: 790 | P379: TCCO | Q379: E | R379: 0.15 | S379: 0.17 | T379: C | U379: 0 | V379: 0 | W379: YES | X379: PARTIAL | Y379: 1.03 | Z379: NONE | AA379: 0
A380: 8313W | B380: GRACE AVENUE E/HORNET DRIVE | C380: SR 17/TENTH STREET | D380: 30TH STREET | E380: 2U | F380: L02 | G380: 1.1 | H380: URBAN COLLECTOR | I380: 3400 | J380: 2 | K380: 0.51 | L380: 0.075 | M380: 124 | N380: C | O380: 790 | P380: TCCO | Q380: E | R380: 0.16 | S380: 0.17 | T380: C | U380: 0 | V380: 0 | W380: YES | X380: PARTIAL | Y380: 1.03 | Z380: NONE | AA380: 0
A381: 8022E | B381: GRANADA STREET | C381: FLORIDA AVENUE N | D381: WEST LAKE PARKER DRIVE | E381: 2U | F381: L02 | G381: 0.7 | H381: URBAN COLLECTOR | I381: 4700 | J381: 2 | K381: 0.49 | L381: 0.09 | M381: 207 | N381: C | O381: 790 | P381: TRANSITIONING | Q381: D | R381: 0.26 | S381: 0.29 | T381: C | U381: 47 | V381: 8.19 | W381: NO | X381: PARTIAL | Y381: 1.85 | Z381: NONE | AA381: 0
A382: 8022W | B382: GRANADA STREET | C382: FLORIDA AVENUE N | D382: WEST LAKE PARKER DRIVE | E382: 2U | F382: L02 | G382: 0.7 | H382: URBAN COLLECTOR | I382: 4700 | J382: 2 | K382: 0.51 | L382: 0.09 | M382: 216 | N382: C | O382: 790 | P382: TRANSITIONING | Q382: D | R382: 0.27 | S382: 0.3 | T382: C | U382: 47 | V382: 8.19 | W382: NO | X382: PARTIAL | Y382: 1.85 | Z382: NONE | AA382: 0
A383: 8314N | B383: GREEN ROAD | C383: DAUGHTERY RD W | D383: DUFF RD | E383: 2U | F383: L02 | G383: 1 | H383: URBAN COLLECTOR | I383: 6700 | J383: 2 | K383: 0.49 | L383: 0.09 | M383: 295 | N383: C | O383: 790 | P383: TRANSITIONING | Q383: D | R383: 0.37 | S383: 0.41 | T383: C | U383: 1 | V383: 0.081 | W383: YES | X383: PARTIAL | Y383: 1.01 | Z383: NONE | AA383: 0
...

Sheet Input
L6: Exiting | O6: Improved | R6: =$AB$6&" Existing Conditions" -> Existing Conditions | AJ6: Daily/2way/Directional per Agency
B7: Seg | C7: Segment Information | F7: Exist | G7: Imp | H7: LOS | I7: Functional | J7: Facility | K7: Context | L7: Daily | M7: 2-Way | N7: Dir | O7: Daily | P7: Peak | Q7: Dir | R7: Daily | U7: AM 2-Way | X7: PM 2-Way -2 HR Vol | AA7: AM Directional | AE7: PM Directional | AI7: GR | AJ7: Adjusted Service Volumes
B8: ID | C8: Roadway | D8: From | E8: To | F8: Lns | G8: Lns | H8: Std | I8: Classification | J8: Type | K8: Classification | L8: Cap | M8: Cap | N8: Cap | O8: Cap | P8: Cap | Q8: Cap | R8: Volume | S8: V/C | T8: LOS | U8: Vol | V8: V/C | W8: LOS | X8: Vol | Y8: V/C | Z8: LOS | AA8: NB/EB | AB8: SB/WB | AC8: V/C | AD8: LOS | AE8: NB/EB | AF8: SB/WB | AG8: V/C | AH8: LOS | AJ8: B | AK8: C | AL8: D | AM8: E
B9: ='Table001 (Page 1-11)'!A5 -> 8301N | C9: ='Table001 (Page 1-11)'!B5 -> ADAMS ROAD/MOHAWK RD | D9: ='Table001 (Page 1-11)'!C5 -> BOLENDER ROAD | E9: ='Table001 (Page 1-11)'!D5 -> CR 559 | F9: ='Table001 (Page 1-11)'!E5 -> 2U | H9: ='Table001 (Page 1-11)'!Q5 -> D | I9: ='Table001 (Page 1-11)'!H5 -> URBAN COLLECTOR | N9: ='Table001 (Page 1-11)'!O5 -> 790 | R9: ='Table001 (Page 1-11)'!I5 -> 3800 | AE9: ='Table001 (Page 1-11)'!M5 -> 168 | AG9: ='Table001 (Page 1-11)'!R5 -> 0.21 | AH9: ='Table001 (Page 1-11)'!Q5 -> D | AI9: ='Table001 (Page 1-11)'!J5 -> 2
B10: ='Table001 (Page 1-11)'!A6 -> 8301S | C10: ='Table001 (Page 1-11)'!B6 -> ADAMS ROAD/MOHAWK RD | D10: ='Table001 (Page 1-11)'!C6 -> BOLENDER ROAD | E10: ='Table001 (Page 1-11)'!D6 -> CR 559 | F10: ='Table001 (Page 1-11)'!E6 -> 2U | H10: ='Table001 (Page 1-11)'!Q6 -> D | I10: ='Table001 (Page 1-11)'!H6 -> URBAN COLLECTOR | N10: ='Table001 (Page 1-11)'!O6 -> 790 | R10: ='Table001 (Page 1-11)'!I6 -> 3800 | AE10: ='Table001 (Page 1-11)'!M6 -> 174 | AG10: ='Table001 (Page 1-11)'!R6 -> 0.22 | AH10: ='Table001 (Page 1-11)'!Q6 -> D | AI10: ='Table001 (Page 1-11)'!J6 -> 2
B11: ='Table001 (Page 1-11)'!A7 -> 8302E | C11: ='Table001 (Page 1-11)'!B7 -> ALAMO DRIVE | D11: ='Table001 (Page 1-11)'!C7 -> OLD HIGHWAY 37 | E11: ='Table001 (Page 1-11)'!D7 -> SR 37 | F11: ='Table001 (Page 1-11)'!E7 -> 2U | H11: ='Table001 (Page 1-11)'!Q7 -> E | I11: ='Table001 (Page 1-11)'!H7 -> URBAN COLLECTOR | N11: ='Table001 (Page 1-11)'!O7 -> 790 | R11: ='Table001 (Page 1-11)'!I7 -> 8500 | AE11: ='Table001 (Page 1-11)'!M7 -> 297 | AG11: ='Table001 (Page 1-11)'!R7 -> 0.38 | AH11: ='Table001 (Page 1-11)'!Q7 -> E | AI11: ='Table001 (Page 1-11)'!J7 -> 2
B12: ='Table001 (Page 1-11)'!A8 -> 8302W | C12: ='Table001 (Page 1-11)'!B8 -> ALAMO DRIVE | D12: ='Table001 (Page 1-11)'!C8 -> OLD HIGHWAY 37 | E12: ='Table001 (Page 1-11)'!D8 -> SR 37 | F12: ='Table001 (Page 1-11)'!E8 -> 2U | H12: ='Table001 (Page 1-11)'!Q8 -> E | I12: ='Table001 (Page 1-11)'!H8 -> URBAN COLLECTOR | N12: ='Table001 (Page 1-11)'!O8 -> 790 | R12: ='Table001 (Page 1-11)'!I8 -> 8500 | AE12: ='Table001 (Page 1-11)'!M8 -> 309 | AG12: ='Table001 (Page 1-11)'!R8 -> 0.39 | AH12: ='Table001 (Page 1-11)'!Q8 -> E | AI12: ='Table001 (Page 1-11)'!J8 -> 2
B13: ='Table001 (Page 1-11)'!A9 -> 8303E | C13: ='Table001 (Page 1-11)'!B9 -> ALAMO DRIVE | D13: ='Table001 (Page 1-11)'!C9 -> SR 563 (HARDEN BLVD S) | E13: ='Table001 (Page 1-11)'!D9 -> OLD HIGHWAY 37 | F13: ='Table001 (Page 1-11)'!E9 -> 2U | H13: ='Table001 (Page 1-11)'!Q9 -> D | I13: ='Table001 (Page 1-11)'!H9 -> URBAN COLLECTOR | N13: ='Table001 (Page 1-11)'!O9 -> 790 | R13: ='Table001 (Page 1-11)'!I9 -> 5000 | AE13: ='Table001 (Page 1-11)'!M9 -> 221 | AG13: ='Table001 (Page 1-11)'!R9 -> 0.28 | AH13: ='Table001 (Page 1-11)'!Q9 -> D | AI13: ='Table001 (Page 1-11)'!J9 -> 2
B14: ='Table001 (Page 1-11)'!A10 -> 8303W | C14: ='Table001 (Page 1-11)'!B10 -> ALAMO DRIVE | D14: ='Table001 (Page 1-11)'!C10 -> SR 563 (HARDEN BLVD S) | E14: ='Table001 (Page 1-11)'!D10 -> OLD HIGHWAY 37 | F14: ='Table001 (Page 1-11)'!E10 -> 2U | H14: ='Table001 (Page 1-11)'!Q10 -> D | I14: ='Table001 (Page 1-11)'!H10 -> URBAN COLLECTOR | N14: ='Table001 (Page 1-11)'!O10 -> 790 | R14: ='Table001 (Page 1-11)'!I10 -> 5000 | AE14: ='Table001 (Page 1-11)'!M10 -> 230 | AG14: ='Table001 (Page 1-11)'!R10 -> 0.29 | AH14: ='Table001 (Page 1-11)'!Q10 -> D | AI14: ='Table001 (Page 1-11)'!J10 -> 2
B15: ='Table001 (Page 1-11)'!A11 -> 4010E | C15: ='Table001 (Page 1-11)'!B11 -> ALTURAS-BABSON PARK CUTOFF RD | D15: ='Table001 (Page 1-11)'!C11 -> CR 559 | E15: ='Table001 (Page 1-11)'!D11 -> US 27 | F15: ='Table001 (Page 1-11)'!E11 -> 2U | H15: ='Table001 (Page 1-11)'!Q11 -> C | I15: ='Table001 (Page 1-11)'!H11 -> RURAL MAJOR COLLECTOR | N15: ='Table001 (Page 1-11)'!O11 -> 450 | R15: ='Table001 (Page 1-11)'!I11 -> 1900 | AE15: ='Table001 (Page 1-11)'!M11 -> 84 | AG15: ='Table001 (Page 1-11)'!R11 -> 0.19 | AH15: ='Table001 (Page 1-11)'!Q11 -> C | AI15: ='Table001 (Page 1-11)'!J11 -> 2
B16: ='Table001 (Page 1-11)'!A12 -> 4010W | C16: ='Table001 (Page 1-11)'!B12 -> ALTURAS-BABSON PARK CUTOFF RD | D16: ='Table001 (Page 1-11)'!C12 -> CR 559 | E16: ='Table001 (Page 1-11)'!D12 -> US 27 | F16: ='Table001 (Page 1-11)'!E12 -> 2U | H16: ='Table001 (Page 1-11)'!Q12 -> C | I16: ='Table001 (Page 1-11)'!H12 -> RURAL MAJOR COLLECTOR | N16: ='Table001 (Page 1-11)'!O12 -> 450 | R16: ='Table001 (Page 1-11)'!I12 -> 1900 | AE16: ='Table001 (Page 1-11)'!M12 -> 87 | AG16: ='Table001 (Page 1-11)'!R12 -> 0.19 | AH16: ='Table001 (Page 1-11)'!Q12 -> C | AI16: ='Table001 (Page 1-11)'!J12 -> 2
B17: ='Table001 (Page 1-11)'!A13 -> 4011N | C17: ='Table001 (Page 1-11)'!B13 -> AMERICAN SUPERIOR BLVD/HOOVER RD/SHELL RD/LK ELOISE DR W | D17: ='Table001 (Page 1-11)'!C13 -> CR 655 (SNIVELY AVE) | E17: ='Table001 (Page 1-11)'!D13 -> AVE Z SE | F17: ='Table001 (Page 1-11)'!E13 -> 2U | H17: ='Table001 (Page 1-11)'!Q13 -> D | I17: ='Table001 (Page 1-11)'!H13 -> URBAN COLLECTOR | N17: ='Table001 (Page 1-11)'!O13 -> 790 | R17: ='Table001 (Page 1-11)'!I13 -> 3300 | AE17: ='Table001 (Page 1-11)'!M13 -> 146 | AG17: ='Table001 (Page 1-11)'!R13 -> 0.18 | AH17: ='Table001 (Page 1-11)'!Q13 -> D | AI17: ='Table001 (Page 1-11)'!J13 -> 2
B18: ='Table001 (Page 1-11)'!A14 -> 4011S | C18: ='Table001 (Page 1-11)'!B14 -> AMERICAN SUPERIOR BLVD/HOOVER RD/SHELL RD/LK ELOISE DR W | D18: ='Table001 (Page 1-11)'!C14 -> CR 655 (SNIVELY AVE) | E18: ='Table001 (Page 1-11)'!D14 -> AVE Z SE | F18: ='Table001 (Page 1-11)'!E14 -> 2U | H18: ='Table001 (Page 1-11)'!Q14 -> D | I18: ='Table001 (Page 1-11)'!H14 -> URBAN COLLECTOR | N18: ='Table001 (Page 1-11)'!O14 -> 790 | R18: ='Table001 (Page 1-11)'!I14 -> 3300 | AE18: ='Table001 (Page 1-11)'!M14 -> 151 | AG18: ='Table001 (Page 1-11)'!R14 -> 0.19 | AH18: ='Table001 (Page 1-11)'!Q14 -> D | AI18: ='Table001 (Page 1-11)'!J14 -> 2
B19: ='Table001 (Page 1-11)'!A15 -> 4012E | C19: ='Table001 (Page 1-11)'!B15 -> ARIANA ST | D19: ='Table001 (Page 1-11)'!C15 -> WABASH AVE S | E19: ='Table001 (Page 1-11)'!D15 -> SR 563 (HARDEN BLVD) | F19: ='Table001 (Page 1-11)'!E15 -> 2U | H19: ='Table001 (Page 1-11)'!Q15 -> D | I19: ='Table001 (Page 1-11)'!H15 -> URBAN COLLECTOR | N19: ='Table001 (Page 1-11)'!O15 -> 790 | R19: ='Table001 (Page 1-11)'!I15 -> 10900 | AE19: ='Table001 (Page 1-11)'!M15 -> 381 | AG19: ='Table001 (Page 1-11)'!R15 -> 0.48 | AH19: ='Table001 (Page 1-11)'!Q15 -> D | AI19: ='Table001 (Page 1-11)'!J15 -> 2
B20: ='Table001 (Page 1-11)'!A16 -> 4012W | C20: ='Table001 (Page 1-11)'!B16 -> ARIANA ST | D20: ='Table001 (Page 1-11)'!C16 -> WABASH AVE S | E20: ='Table001 (Page 1-11)'!D16 -> SR 563 (HARDEN BLVD) | F20: ='Table001 (Page 1-11)'!E16 -> 2U | H20: ='Table001 (Page 1-11)'!Q16 -> D | I20: ='Table001 (Page 1-11)'!H16 -> URBAN COLLECTOR | N20: ='Table001 (Page 1-11)'!O16 -> 790 | R20: ='Table001 (Page 1-11)'!I16 -> 10900 | AE20: ='Table001 (Page 1-11)'!M16 -> 396 | AG20: ='Table001 (Page 1-11)'!R16 -> 0.5 | AH20: ='Table001 (Page 1-11)'!Q16 -> D | AI20: ='Table001 (Page 1-11)'!J16 -> 2
... B1119: ='Table001 (Page 1-11)'!A1115 -> 8053S | C1119: ='Table001 (Page 1-11)'!B1115 -> YATES ROAD | D1119: ='Table001 (Page 1-11)'!C1115 -> EWELL ROAD | E1119: ='Table001 (Page 1-11)'!D1115 -> PIPKIN ROAD W | F1119: ='Table001 (Page 1-11)'!E1115 -> 2U | H1119: ='Table001 (Page 1-11)'!Q1115 -> E | I1119: ='Table001 (Page 1-11)'!H1115 -> URBAN COLLECTOR | N1119: ='Table001 (Page 1-11)'!O1115 -> 790 | R1119: ='Table001 (Page 1-11)'!I1115 -> 5900 | AE1119: ='Table001 (Page 1-11)'!M1115 -> 214 | AG1119: ='Table001 (Page 1-11)'!R1115 -> 0.27 | AH1119: ='Table001 (Page 1-11)'!Q1115 -> E | AI1119: ='Table001 (Page 1-11)'!J1115 -> 2
