Workbook

Sheet 2025MasterFile-Stat
A1: Class | B1: Roadway | C1: Segment | D1: Source | E1: 2022 Station | F1: 2025 Station | G1: Lns | H1: LOS Std | I1: Speed Limit | J1: Location
J2: Lat | K2: Long
A3: Min Coll | B3: 10th St | C3: Alabama Ave to Sheeler Ave | D3: CITY | E3: 411 | F3: 411 | G3: 2L | H3: E | I3: 30 | J3: 28.66578 | K3: -81.49576
A4: Min Coll | B4: 13th St | C4: Ocoee-Apopka Rd to Park Ave | D4: CITY | E4: 840 | F4: 840 | G4: 2L | H4: E | I4: 25 | J4: 28.662029 | K4: -81.514872
A5: Min Coll | B5: 13th St | C5: Park Ave to Apopka Blvd | D5: CITY | E5: 841 | F5: 841 | G5: 2L | H5: E | I5: 25 | J5: 28.662083 | K5: -81.500375
A6: Min Coll | B6: 2nd St (Monroe Ave) | C6: Central Ave to Park Ave | D6: CITY | E6: 401 | F6: 401 | G6: 2L | H6: D | I6: 30 | J6: 28.675534 | K6: -81.511075
A7: Min Coll | B7: 5th St | C7: Park Ave to Highland Ave | D7: CITY | E7: 403 | F7: 403 | G7: 2L | H7: D | I7: 30 | J7: 28.671882 | K7: -81.507758
A8: Min Coll | B8: 6th St | C8: Park Ave to Alabama Ave | D8: CITY | E8: 650 | F8: 650 | G8: 2L | H8: D | I8: 30 | J8: 28.670699 | K8: -81.506454
A9: Min Coll | B9: 6th St | C9: Alabama Ave to US 441 | D9: CITY | E9: 410 | F9: 410 | G9: 2L | H9: D | I9: 30 | J9: 28.67073 | K9: -81.497702
A10: Min Coll | B10: 8th St | C10: Park Ave to Highland Ave | D10: CITY | E10: 404 | F10: 404 | G10: 2L | H10: D | I10: 30 | J10: 28.668232 | K10: -81.507051
A11: Min Coll | B11: 9th St | C11: Central Ave to Park Ave | D11: CITY | E11: 333 | F11: 333 | G11: 2L | H11: E | I11: 30 | J11: 28.667006 | K11: -81.510471
A12: Min Coll | B12: Alabama Ave | C12: Monroe Ave to US 441 | D12: CITY | E12: 409 | F12: 409 | G12: 2L | H12: E | I12: 25 | J12: 28.674095 | K12: -81.50183
A13: Min Coll | B13: Appy Ln | C13: Plymouth-Sorrento Rd (CR 437) to Jason Dwelley Pkwy | D13: CITY | E13: 971 | F13: 971 | G13: 2L | H13: E | I13: 35 | J13: 28.742714 | K13: -81.550574
A14: Min Coll | B14: Binion Rd/Orange Ave | C14: Lakeview Dr to US 441 | D14: COUNTY | E14: 554 | F14: 404* | G14: 2L | H14: E | I14: 40 | J14: 28.688916 | K14: -81.554052
A15: Min Coll | B15: Binion Rd/Orange Ave | C15: Boy Scout Rd to Lakeview Dr | D15: COUNTY | E15: 553 | F15: (404, 327)* | G15: 2L | H15: E | I15: 40 | J15: 28.670248 | K15: -81.550394
A16: Min Coll | B16: Binion Rd/Orange Ave | C16: Ocoee-Apopka Rd to Harmon Rd | D16: COUNTY | E16: 28 | F16: 28* | G16: 2L | H16: E | I16: 55 | J16: 28.635266 | K16: -81.55007
A17: Min Coll | B17: Binion Rd/Orange Ave | C17: Harmon Rd to Boy Scout Rd | D17: CITY | E17: 673 | F17: 673 | G17: 2L | H17: E | I17: 55 | J17: 28.657139 | K17: -81.550721
A18: Min Coll | B18: Boy Scout Rd | C18: Binion Rd to Ocoee-Apopka Rd | D18: CITY | E18: 556 | F18: 556 | G18: 2L | H18: E | I18: 45 | J18: 28.661952 | K18: -81.538743
A19: Min Coll | B19: Bradshaw Rd | C19: US 441 to Ocoee-Apopka Rd | D19: CITY | E19: 557 | F19: 557 | G19: 2L | H19: E | I19: 45 | J19: 28.673357 | K19: -81.521741
A20: Min Art | B20: CR 424 (Alabama Ave/Apopka Blvd) | C20: Hiawassee Rd to Overland Rd | D20: COUNTY | E20: 33.1 | F20: 33* | G20: 2L | H20: E | I20: 35 | J20: 28.64167 | K20: -81.462885
A21: Min Art | B21: CR 424 (Alabama Ave/Apopka Blvd) | C21: 8th St to Sheeler Rd | D21: COUNTY | E21: 651 | F21: 1008* | G21: 2L | H21: E | I21: 45 | J21: 28.664812 | K21: -81.497702
A22: Min Art | B22: CR 424 (Alabama Ave/Apopka Blvd) | C22: Overland Rd to US 441 | D22: CITY | E22: 671 | F22: 671 | G22: 2L | H22: E | I22: 35 | J22: 28.635611 | K22: -81.454984
A23: Min Art | B23: CR 424 (Alabama Ave/Apopka Blvd) | C23: Lakeville Rd to Hiawassee Rd | D23: CITY | E23: 658 | F23: 658 | G23: 3L | H23: E | I23: 40 | J23: 28.651139 | K23: -81.477106
A24: Min Art | B24: CR 424 (Alabama Ave/Apopka Blvd) | C24: Sheeler Rd to Lakeville Rd | D24: COUNTY | E24: 653 | F24: 7033* | G24: 2L | H24: E | I24: 40 | J24: 28.654673 | K24: -81.486935
A25: Min Art | B25: CR 424 (Alabama Ave/Apopka Blvd) | C25: US 441 to 8th St | D25: CITY | E25: 670 | F25: 670 | G25: 2L | H25: E | I25: 45 | J25: 28.671607 | K25: -81.502026
A26: Min Art | B26: CR 435 (Rock Spring Rd/Park Ave/Clarcona Rd) | C26: Keene Rd to McCormick Rd | D26: COUNTY | E26: 565 | F26: (32, 7004)* | G26: 2L | H26: E | I26: 45 | J26: 28.632718 | K26: -81.498788
A27: Min Art | B27: CR 435 (Rock Spring Rd/Park Ave/Clarcona Rd) | C27: M. Gladden Blvd to Cleveland St | D27: COUNTY | E27: 328.1 | F27: 328* | G27: 2L | H27: E | I27: 30 | J27: 28.66513 | K27: -81.50937
A28: Min Art | B28: CR 435 (Rock Spring Rd/Park Ave/Clarcona Rd) | C28: Votaw Rd to Orange St | D28: COUNTY | E28: 426 | F28: 426* | G28: 5L | H28: E | I28: 35 | J28: 28.6809 | K28: -81.5095
A29: Min Art | B29: CR 435 (Rock Spring Rd/Park Ave/Clarcona Rd) | C29: Welch Rd to Sandpiper Rd | D29: COUNTY | E29: 21 | F29: 21* | G29: 5L | H29: E | I29: 45 | J29: 28.6985 | K29: -81.5092
A30: Min Art | B30: CR 435 (Rock Spring Rd/Park Ave/Clarcona Rd) | C30: Ponkan Rd to Welch Rd | D30: COUNTY | E30: 19 | F30: 19* | G30: 5L | H30: E | I30: 45 | J30: 28.7145 | K30: -81.509
A31: Min Art | B31: CR 435 (Rock Spring Rd/Park Ave/Clarcona Rd) | C31: McCormick Rd to Clarcona-Ocoee Rd | D31: CITY | E31: 7004 | F31: 7004 | G31: 2L | H31: E | I31: 45 | J31: 28.618562 | K31: -81.499335
A32: Min Art | B32: CR 435 (Rock Spring Rd/Park Ave/Clarcona Rd) | C32: Sandpiper Rd to Votaw Rd | D32: CITY | E32: 516 | F32: 516 | G32: 5L | H32: E | I32: 35 | J32: 28.690042 | K32: -81.509411
A33: Min Art | B33: CR 435 (Rock Spring Rd/Park Ave/Clarcona Rd) | C33: US 441 to M. Gladden Blvd | D33: CITY | E33: 563 | F33: 563 | G33: 2L | H33: E | I33: 30 | J33: 28.670468 | K33: -81.509453
A34: Min Art | B34: CR 435 (Rock Spring Rd/Park Ave/Clarcona Rd) | C34: Orange St to US 441 | D34: CITY | E34: 580 | F34: 580 | G34: 5L | H34: E | I34: 35 | J34: 28.675129 | K34: -81.509426
A35: Min Art | B35: CR 435 (Rock Spring Rd/Park Ave/Clarcona Rd) | C35: Cleveland St to Keene Rd | D35: COUNTY | E35: 564 | F35: 7005* | G35: 2L | H35: E | I35: 45 | J35: 28.648251 | K35: -81.505598
A36: Min Art | B36: CR 435 (Rock Spring Rd/Park Ave/Clarcona Rd) | C36: Kelly Park Rd to Ponkan Rd | D36: COUNTY | E36: 18.1 | F36: 18* | G36: 4LD | H36: E | I36: 45 | J36: 28.7367 | K36: -81.509
A37: Min Art | B37: CR 437A (Ocoee-Apopka Rd/Michael Gladden Blvd/Central Ave) | C37: Harmon Rd to Bradshaw Rd | D37: COUNTY | E37: 27 | F37: 27* | G37: 2L | H37: E | I37: 45 | J37: 28.66438 | K37: -81.522
A38: Min Art | B38: CR 437A (Ocoee-Apopka Rd/Michael Gladden Blvd/Central Ave) | C38: Bradshaw Rd to Park Ave | D38: COUNTY | E38: 7083 | F38: 7083* | G38: 2L | H38: E | I38: 35 | J38: 28.66641 | K38: -81.51956
A39: Min Art | B39: CR 437A (Ocoee-Apopka Rd/Michael Gladden Blvd/Central Ave) | C39: Alston Bay Blvd to Harmon Rd | D39: COUNTY | E39: 559 | F39: (27, 29)* | G39: 4LD | H39: E | I39: 45 | J39: 28.647932 | K39: -81.538075
A40: Min Art | B40: CR 437A (Ocoee-Apopka Rd/Michael Gladden Blvd/Central Ave) | C40: Keene Rd to Alston Bay Blvd | D40: CITY | E40: 29 | F40: 29 | G40: 2L | H40: E | I40: 45 | J40: 28.64353 | K40: -81.53885
...

Sheet Input
Y1: Existing Year
Y2: 2024
L6: Exiting | O6: Improved | R6: =$AA$3&" Existing Conditions" -> Existing Conditions | AJ6: Daily/2way/Directional per Agency
B7: Seg | C7: Segment Information | F7: Exist | G7: Imp | H7: LOS | I7: Functional | J7: Facility | K7: Context | L7: Daily | M7: 2-Way | N7: Dir | O7: Daily | P7: Peak | Q7: Dir | R7: Daily | U7: AM 2-Way | X7: PM 2-Way | AA7: AM Directional | AE7: PM Directional | AI7: GR | AJ7: Adjusted Service Volumes
B8: ID | C8: Roadway | D8: From | E8: To | F8: Lns | G8: Lns | H8: Std | I8: Class | J8: Type | K8: Classification | L8: Cap | M8: Cap | N8: Cap | O8: Cap | P8: Cap | Q8: Cap | R8: Volume | S8: V/C | T8: LOS | U8: Vol | V8: V/C | W8: LOS | X8: Vol | Y8: V/C | Z8: LOS | AA8: NB/EB | AB8: SB/WB | AC8: V/C | AD8: LOS | AE8: NB/EB | AF8: SB/WB | AG8: V/C | AH8: LOS | AJ8: B | AK8: C | AL8: D | AM8: E
B9: ='2025MasterFile-Stat'!F3 -> 411 | C9: ='2025MasterFile-Stat'!B3 -> 10th St | D9: =LEFT('2025MasterFile-Stat'!C3,FIND(" to ",'2025MasterFile-Stat'!C3)-1) -> Alabama Ave | E9: =RIGHT('2025MasterFile-Stat'!C3,LEN('2025MasterFile-Stat'!C3)-FIND(" to ",'2025MasterFile-Stat'!C3)-3) -> Sheeler Ave | F9: ='2025MasterFile-Stat'!G3 -> 2L | H9: ='2025MasterFile-Stat'!H3 -> E | I9: ='2025MasterFile-Stat'!A3 -> Min Coll | L9: =IF(Cap!H3="A",Cap!O3, IF(Cap!H3="B",Cap!P3, IF(Cap!H3="C",Cap!Q3, IF(Cap!H3="D",Cap!R3, IF(Cap!H3="E",Cap!S3,""))))) -> 10100 | N9: =IF(Cap!H3="A",Cap!J3, IF(Cap!H3="B",Cap!K3, IF(Cap!H3="C",Cap!L3, IF(Cap!H3="D",Cap!M3, IF(Cap!H3="E",Cap!N3,""))))) -> 520 | R9: =LOS!J3 -> 467 | T9: =LOS!K3 -> C | AA9: =LOS!L3 -> 18 | AB9: =LOS!M3 -> 19 | AD9: =LOS!Q3 -> C | AE9: =LOS!R3 -> 18 | AF9: =LOS!S3 -> 18 | AH9: =LOS!W3 -> C | AI9: =(Trend!L3) -> -0.8137045 | AJ9: =Cap!K3 -> 0 | AK9: =Cap!L3 -> 240 | AL9: =Cap!M3 -> 490 | AM9: =Cap!N3 -> 520
B10: ='2025MasterFile-Stat'!F4 -> 840 | C10: ='2025MasterFile-Stat'!B4 -> 13th St | D10: =LEFT('2025MasterFile-Stat'!C4,FIND(" to ",'2025MasterFile-Stat'!C4)-1) -> Ocoee-Apopka Rd | E10: =RIGHT('2025MasterFile-Stat'!C4,LEN('2025MasterFile-Stat'!C4)-FIND(" to ",'2025MasterFile-Stat'!C4)-3) -> Park Ave | F10: ='2025MasterFile-Stat'!G4 -> 2L | H10: ='2025MasterFile-Stat'!H4 -> E | I10: ='2025MasterFile-Stat'!A4 -> Min Coll | L10: =IF(Cap!H4="A",Cap!O4, IF(Cap!H4="B",Cap!P4, IF(Cap!H4="C",Cap!Q4, IF(Cap!H4="D",Cap!R4, IF(Cap!H4="E",Cap!S4,""))))) -> 10100 | N10: =IF(Cap!H4="A",Cap!J4, IF(Cap!H4="B",Cap!K4, IF(Cap!H4="C",Cap!L4, IF(Cap!H4="D",Cap!M4, IF(Cap!H4="E",Cap!N4,""))))) -> 520 | R10: =LOS!J4 -> 3017 | T10: =LOS!K4 -> C | AA10: =LOS!L4 -> 101 | AB10: =LOS!M4 -> 130 | AD10: =LOS!Q4 -> C | AE10: =LOS!R4 -> 137 | AF10: =LOS!S4 -> 120 | AH10: =LOS!W4 -> C | AI10: =(Trend!L4) -> 4.0835267 | AJ10: =Cap!K4 -> 0 | AK10: =Cap!L4 -> 240 | AL10: =Cap!M4 -> 490 | AM10: =Cap!N4 -> 520
B11: ='2025MasterFile-Stat'!F5 -> 841 | C11: ='2025MasterFile-Stat'!B5 -> 13th St | D11: =LEFT('2025MasterFile-Stat'!C5,FIND(" to ",'2025MasterFile-Stat'!C5)-1) -> Park Ave | E11: =RIGHT('2025MasterFile-Stat'!C5,LEN('2025MasterFile-Stat'!C5)-FIND(" to ",'2025MasterFile-Stat'!C5)-3) -> Apopka Blvd | F11: ='2025MasterFile-Stat'!G5 -> 2L | H11: ='2025MasterFile-Stat'!H5 -> E | I11: ='2025MasterFile-Stat'!A5 -> Min Coll | L11: =IF(Cap!H5="A",Cap!O5, IF(Cap!H5="B",Cap!P5, IF(Cap!H5="C",Cap!Q5, IF(Cap!H5="D",Cap!R5, IF(Cap!H5="E",Cap!S5,""))))) -> 10100 | N11: =IF(Cap!H5="A",Cap!J5, IF(Cap!H5="B",Cap!K5, IF(Cap!H5="C",Cap!L5, IF(Cap!H5="D",Cap!M5, IF(Cap!H5="E",Cap!N5,""))))) -> 520 | R11: =LOS!J5 -> 3788 | T11: =LOS!K5 -> C | AA11: =LOS!L5 -> 150 | AB11: =LOS!M5 -> 88 | AD11: =LOS!Q5 -> C | AE11: =LOS!R5 -> 129 | AF11: =LOS!S5 -> 196 | AH11: =LOS!W5 -> C | AI11: =(Trend!L5) -> 1.9244984 | AJ11: =Cap!K5 -> 0 | AK11: =Cap!L5 -> 240 | AL11: =Cap!M5 -> 490 | AM11: =Cap!N5 -> 520
B12: ='2025MasterFile-Stat'!F6 -> 401 | C12: ='2025MasterFile-Stat'!B6 -> 2nd St (Monroe Ave) | D12: =LEFT('2025MasterFile-Stat'!C6,FIND(" to ",'2025MasterFile-Stat'!C6)-1) -> Central Ave | E12: =RIGHT('2025MasterFile-Stat'!C6,LEN('2025MasterFile-Stat'!C6)-FIND(" to ",'2025MasterFile-Stat'!C6)-3) -> Park Ave | F12: ='2025MasterFile-Stat'!G6 -> 2L | H12: ='2025MasterFile-Stat'!H6 -> D | I12: ='2025MasterFile-Stat'!A6 -> Min Coll | L12: =IF(Cap!H6="A",Cap!O6, IF(Cap!H6="B",Cap!P6, IF(Cap!H6="C",Cap!Q6, IF(Cap!H6="D",Cap!R6, IF(Cap!H6="E",Cap!S6,""))))) -> 9600 | N12: =IF(Cap!H6="A",Cap!J6, IF(Cap!H6="B",Cap!K6, IF(Cap!H6="C",Cap!L6, IF(Cap!H6="D",Cap!M6, IF(Cap!H6="E",Cap!N6,""))))) -> 490 | R12: =LOS!J6 -> 897 | T12: =LOS!K6 -> C | AA12: =LOS!L6 -> 31 | AB12: =LOS!M6 -> 32 | AD12: =LOS!Q6 -> C | AE12: =LOS!R6 -> 40 | AF12: =LOS!S6 -> 50 | AH12: =LOS!W6 -> C | AI12: =(Trend!L6) -> -5.3957637 | AJ12: =Cap!K6 -> 0 | AK12: =Cap!L6 -> 240 | AL12: =Cap!M6 -> 490 | AM12: =Cap!N6 -> 520
B13: ='2025MasterFile-Stat'!F7 -> 403 | C13: ='2025MasterFile-Stat'!B7 -> 5th St | D13: =LEFT('2025MasterFile-Stat'!C7,FIND(" to ",'2025MasterFile-Stat'!C7)-1) -> Park Ave | E13: =RIGHT('2025MasterFile-Stat'!C7,LEN('2025MasterFile-Stat'!C7)-FIND(" to ",'2025MasterFile-Stat'!C7)-3) -> Highland Ave | F13: ='2025MasterFile-Stat'!G7 -> 2L | H13: ='2025MasterFile-Stat'!H7 -> D | I13: ='2025MasterFile-Stat'!A7 -> Min Coll | L13: =IF(Cap!H7="A",Cap!O7, IF(Cap!H7="B",Cap!P7, IF(Cap!H7="C",Cap!Q7, IF(Cap!H7="D",Cap!R7, IF(Cap!H7="E",Cap!S7,""))))) -> 9600 | N13: =IF(Cap!H7="A",Cap!J7, IF(Cap!H7="B",Cap!K7, IF(Cap!H7="C",Cap!L7, IF(Cap!H7="D",Cap!M7, IF(Cap!H7="E",Cap!N7,""))))) -> 490 | R13: =LOS!J7 -> 1778 | T13: =LOS!K7 -> C | AA13: =LOS!L7 -> 113 | AB13: =LOS!M7 -> 96 | AD13: =LOS!Q7 -> C | AE13: =LOS!R7 -> 83 | AF13: =LOS!S7 -> 63 | AH13: =LOS!W7 -> C | AI13: =(Trend!L7) -> -29.769404 | AJ13: =Cap!K7 -> 0 | AK13: =Cap!L7 -> 240 | AL13: =Cap!M7 -> 490 | AM13: =Cap!N7 -> 520
B14: ='2025MasterFile-Stat'!F8 -> 650 | C14: ='2025MasterFile-Stat'!B8 -> 6th St | D14: =LEFT('2025MasterFile-Stat'!C8,FIND(" to ",'2025MasterFile-Stat'!C8)-1) -> Park Ave | E14: =RIGHT('2025MasterFile-Stat'!C8,LEN('2025MasterFile-Stat'!C8)-FIND(" to ",'2025MasterFile-Stat'!C8)-3) -> Alabama Ave | F14: ='2025MasterFile-Stat'!G8 -> 2L | H14: ='2025MasterFile-Stat'!H8 -> D | I14: ='2025MasterFile-Stat'!A8 -> Min Coll | L14: =IF(Cap!H8="A",Cap!O8, IF(Cap!H8="B",Cap!P8, IF(Cap!H8="C",Cap!Q8, IF(Cap!H8="D",Cap!R8, IF(Cap!H8="E",Cap!S8,""))))) -> 9600 | N14: =IF(Cap!H8="A",Cap!J8, IF(Cap!H8="B",Cap!K8, IF(Cap!H8="C",Cap!L8, IF(Cap!H8="D",Cap!M8, IF(Cap!H8="E",Cap!N8,""))))) -> 490 | R14: =LOS!J8 -> 2283 | T14: =LOS!K8 -> C | AA14: =LOS!L8 -> 48 | AB14: =LOS!M8 -> 115 | AD14: =LOS!Q8 -> C | AE14: =LOS!R8 -> 69 | AF14: =LOS!S8 -> 165 | AH14: =LOS!W8 -> C | AI14: =(Trend!L8) -> -17.542707 | AJ14: =Cap!K8 -> 0 | AK14: =Cap!L8 -> 240 | AL14: =Cap!M8 -> 490 | AM14: =Cap!N8 -> 520
B15: ='2025MasterFile-Stat'!F9 -> 410 | C15: ='2025MasterFile-Stat'!B9 -> 6th St | D15: =LEFT('2025MasterFile-Stat'!C9,FIND(" to ",'2025MasterFile-Stat'!C9)-1) -> Alabama Ave | E15: =RIGHT('2025MasterFile-Stat'!C9,LEN('2025MasterFile-Stat'!C9)-FIND(" to ",'2025MasterFile-Stat'!C9)-3) -> US 441 | F15: ='2025MasterFile-Stat'!G9 -> 2L | H15: ='2025MasterFile-Stat'!H9 -> D | I15: ='2025MasterFile-Stat'!A9 -> Min Coll | L15: =IF(Cap!H9="A",Cap!O9, IF(Cap!H9="B",Cap!P9, IF(Cap!H9="C",Cap!Q9, IF(Cap!H9="D",Cap!R9, IF(Cap!H9="E",Cap!S9,""))))) -> 9600 | N15: =IF(Cap!H9="A",Cap!J9, IF(Cap!H9="B",Cap!K9, IF(Cap!H9="C",Cap!L9, IF(Cap!H9="D",Cap!M9, IF(Cap!H9="E",Cap!N9,""))))) -> 490 | R15: =LOS!J9 -> 1435 | T15: =LOS!K9 -> C | AA15: =LOS!L9 -> 50 | AB15: =LOS!M9 -> 57 | AD15: =LOS!Q9 -> C | AE15: =LOS!R9 -> 57 | AF15: =LOS!S9 -> 87 | AH15: =LOS!W9 -> C | AI15: =(Trend!L9) -> -8.2926829 | AJ15: =Cap!K9 -> 0 | AK15: =Cap!L9 -> 240 | AL15: =Cap!M9 -> 490 | AM15: =Cap!N9 -> 520
B16: ='2025MasterFile-Stat'!F10 -> 404 | C16: ='2025MasterFile-Stat'!B10 -> 8th St | D16: =LEFT('2025MasterFile-Stat'!C10,FIND(" to ",'2025MasterFile-Stat'!C10)-1) -> Park Ave | E16: =RIGHT('2025MasterFile-Stat'!C10,LEN('2025MasterFile-Stat'!C10)-FIND(" to ",'2025MasterFile-Stat'!C10)-3) -> Highland Ave | F16: ='2025MasterFile-Stat'!G10 -> 2L | H16: ='2025MasterFile-Stat'!H10 -> D | I16: ='2025MasterFile-Stat'!A10 -> Min Coll | L16: =IF(Cap!H10="A",Cap!O10, IF(Cap!H10="B",Cap!P10, IF(Cap!H10="C",Cap!Q10, IF(Cap!H10="D",Cap!R10, IF(Cap!H10="E",Cap!S10,""))))) -> 9600 | N16: =IF(Cap!H10="A",Cap!J10, IF(Cap!H10="B",Cap!K10, IF(Cap!H10="C",Cap!L10, IF(Cap!H10="D",Cap!M10, IF(Cap!H10="E",Cap!N10,""))))) -> 490 | R16: =LOS!J10 -> 3069 | T16: =LOS!K10 -> C | AA16: =LOS!L10 -> 86 | AB16: =LOS!M10 -> 92 | AD16: =LOS!Q10 -> C | AE16: =LOS!R10 -> 127 | AF16: =LOS!S10 -> 164 | AH16: =LOS!W10 -> C | AI16: =(Trend!L10) -> -16.74161 | AJ16: =Cap!K10 -> 0 | AK16: =Cap!L10 -> 240 | AL16: =Cap!M10 -> 490 | AM16: =Cap!N10 -> 520
B17: ='2025MasterFile-Stat'!F11 -> 333 | C17: ='2025MasterFile-Stat'!B11 -> 9th St | D17: =LEFT('2025MasterFile-Stat'!C11,FIND(" to ",'2025MasterFile-Stat'!C11)-1) -> Central Ave | E17: =RIGHT('2025MasterFile-Stat'!C11,LEN('2025MasterFile-Stat'!C11)-FIND(" to ",'2025MasterFile-Stat'!C11)-3) -> Park Ave | F17: ='2025MasterFile-Stat'!G11 -> 2L | H17: ='2025MasterFile-Stat'!H11 -> E | I17: ='2025MasterFile-Stat'!A11 -> Min Coll | L17: =IF(Cap!H11="A",Cap!O11, IF(Cap!H11="B",Cap!P11, IF(Cap!H11="C",Cap!Q11, IF(Cap!H11="D",Cap!R11, IF(Cap!H11="E",Cap!S11,""))))) -> 10100 | N17: =IF(Cap!H11="A",Cap!J11, IF(Cap!H11="B",Cap!K11, IF(Cap!H11="C",Cap!L11, IF(Cap!H11="D",Cap!M11, IF(Cap!H11="E",Cap!N11,""))))) -> 520 | R17: =LOS!J11 -> 3797 | T17: =LOS!K11 -> C | AA17: =LOS!L11 -> 134 | AB17: =LOS!M11 -> 114 | AD17: =LOS!Q11 -> C | AE17: =LOS!R11 -> 181 | AF17: =LOS!S11 -> 130 | AH17: =LOS!W11 -> C | AI17: =(Trend!L11) -> -6.1416908 | AJ17: =Cap!K11 -> 0 | AK17: =Cap!L11 -> 240 | AL17: =Cap!M11 -> 490 | AM17: =Cap!N11 -> 520
B18: ='2025MasterFile-Stat'!F12 -> 409 | C18: ='2025MasterFile-Stat'!B12 -> Alabama Ave | D18: =LEFT('2025MasterFile-Stat'!C12,FIND(" to ",'2025MasterFile-Stat'!C12)-1) -> Monroe Ave | E18: =RIGHT('2025MasterFile-Stat'!C12,LEN('2025MasterFile-Stat'!C12)-FIND(" to ",'2025MasterFile-Stat'!C12)-3) -> US 441 | F18: ='2025MasterFile-Stat'!G12 -> 2L | H18: ='2025MasterFile-Stat'!H12 -> E | I18: ='2025MasterFile-Stat'!A12 -> Min Coll | L18: =IF(Cap!H12="A",Cap!O12, IF(Cap!H12="B",Cap!P12, IF(Cap!H12="C",Cap!Q12, IF(Cap!H12="D",Cap!R12, IF(Cap!H12="E",Cap!S12,""))))) -> 10100 | N18: =IF(Cap!H12="A",Cap!J12, IF(Cap!H12="B",Cap!K12, IF(Cap!H12="C",Cap!L12, IF(Cap!H12="D",Cap!M12, IF(Cap!H12="E",Cap!N12,""))))) -> 520 | R18: =LOS!J12 -> 297 | T18: =LOS!K12 -> C | AA18: =LOS!L12 -> 9 | AB18: =LOS!M12 -> 8 | AD18: =LOS!Q12 -> C | AE18: =LOS!R12 -> 20 | AF18: =LOS!S12 -> 7 | AH18: =LOS!W12 -> C | AI18: =(Trend!L12) -> -9.4276094 | AJ18: =Cap!K12 -> 0 | AK18: =Cap!L12 -> 240 | AL18: =Cap!M12 -> 490 | AM18: =Cap!N12 -> 520
B19: ='2025MasterFile-Stat'!F13 -> 971 | C19: ='2025MasterFile-Stat'!B13 -> Appy Ln | D19: =LEFT('2025MasterFile-Stat'!C13,FIND(" to ",'2025MasterFile-Stat'!C13)-1) -> Plymouth-Sorrento Rd (CR 437) | E19: =RIGHT('2025MasterFile-Stat'!C13,LEN('2025MasterFile-Stat'!C13)-FIND(" to ",'2025MasterFile-Stat'!C13)-3) -> Jason Dwelley Pkwy | F19: ='2025MasterFile-Stat'!G13 -> 2L | H19: ='2025MasterFile-Stat'!H13 -> E | I19: ='2025MasterFile-Stat'!A13 -> Min Coll | L19: =IF(Cap!H13="A",Cap!O13, IF(Cap!H13="B",Cap!P13, IF(Cap!H13="C",Cap!Q13, IF(Cap!H13="D",Cap!R13, IF(Cap!H13="E",Cap!S13,""))))) -> 14000 | N19: =IF(Cap!H13="A",Cap!J13, IF(Cap!H13="B",Cap!K13, IF(Cap!H13="C",Cap!L13, IF(Cap!H13="D",Cap!M13, IF(Cap!H13="E",Cap!N13,""))))) -> 720 | R19: =LOS!J13 -> 1224 | T19: =LOS!K13 -> C | AA19: =LOS!L13 -> 89 | AB19: =LOS!M13 -> 95 | AD19: =LOS!Q13 -> C | AE19: =LOS!R13 -> 49 | AF19: =LOS!S13 -> 36 | AH19: =LOS!W13 -> C | AI19: =(Trend!L13) -> -2.998366 | AJ19: =Cap!K13 -> 0 | AK19: =Cap!L13 -> 330 | AL19: =Cap!M13 -> 680 | AM19: =Cap!N13 -> 720
B20: ='2025MasterFile-Stat'!F14 -> 404* | C20: ='2025MasterFile-Stat'!B14 -> Binion Rd/Orange Ave | D20: =LEFT('2025MasterFile-Stat'!C14,FIND(" to ",'2025MasterFile-Stat'!C14)-1) -> Lakeview Dr | E20: =RIGHT('2025MasterFile-Stat'!C14,LEN('2025MasterFile-Stat'!C14)-FIND(" to ",'2025MasterFile-Stat'!C14)-3) -> US 441 | F20: ='2025MasterFile-Stat'!G14 -> 2L | H20: ='2025MasterFile-Stat'!H14 -> E | I20: ='2025MasterFile-Stat'!A14 -> Min Coll | L20: =IF(Cap!H14="A",Cap!O14, IF(Cap!H14="B",Cap!P14, IF(Cap!H14="C",Cap!Q14, IF(Cap!H14="D",Cap!R14, IF(Cap!H14="E",Cap!S14,""))))) -> 17700 | N20: =IF(Cap!H14="A",Cap!J14, IF(Cap!H14="B",Cap!K14, IF(Cap!H14="C",Cap!L14, IF(Cap!H14="D",Cap!M14, IF(Cap!H14="E",Cap!N14,""))))) -> 880 | R20: =LOS!J14 -> 6029 | T20: =LOS!K14 -> C | AA20: =LOS!L14 -> 239 | AB20: =LOS!M14 -> 348 | AD20: =LOS!Q14 -> C | AE20: =LOS!R14 -> 320 | AF20: =LOS!S14 -> 230 | AH20: =LOS!W14 -> C | AI20: =(Trend!L14) -> 3.9645844 | AJ20: =Cap!K14 -> 0 | AK20: =Cap!L14 -> 830 | AL20: =Cap!M14 -> 880 | AM20: =Cap!N14 -> 880
... B201: ='2025MasterFile-Stat'!F195 -> 800 | C201: ='2025MasterFile-Stat'!B195 -> Yothers Rd | D201: =LEFT('2025MasterFile-Stat'!C195,FIND(" to ",'2025MasterFile-Stat'!C195)-1) -> US 441 | E201: =RIGHT('2025MasterFile-Stat'!C195,LEN('2025MasterFile-Stat'!C195)-FIND(" to ",'2025MasterFile-Stat'!C195)-3) -> Hermit Smith Rd | F201: ='2025MasterFile-Stat'!G195 -> 2L | H201: ='2025MasterFile-Stat'!H195 -> E | I201: ='2025MasterFile-Stat'!A195 -> Min Coll | L201: =IF(Cap!H195="A",Cap!O195, IF(Cap!H195="B",Cap!P195, IF(Cap!H195="C",Cap!Q195, IF(Cap!H195="D",Cap!R195, IF(Cap!H195="E",Cap!S195,""))))) -> 14000 | N201: =IF(Cap!H195="A",Cap!J195, IF(Cap!H195="B",Cap!K195, IF(Cap!H195="C",Cap!L195, IF(Cap!H195="D",Cap!M195, IF(Cap!H195="E",Cap!N195,""))))) -> 720 | R201: =LOS!J195 -> 2374 | T201: =LOS!K195 -> C | AA201: =LOS!L195 -> 65 | AB201: =LOS!M195 -> 140 | AD201: =LOS!Q195 -> C | AE201: =LOS!R195 -> 129 | AF201: =LOS!S195 -> 79 | AH201: =LOS!W195 -> C | AI201: =(Trend!L195) -> 5.168492 | AJ201: =Cap!K195 -> 0 | AK201: =Cap!L195 -> 330 | AL201: =Cap!M195 -> 680 | AM201: =Cap!N195 -> 720

Sheet Cap
A1: Class | B1: Roadway | C1: Segment | D1: Source | E1: 2022 Station | F1: 2025 Station | G1: Lns | H1: LOS Std | I1: Speed Limit | J1: Peak Hour Directional Service Volumes | O1: Daily Service Volumes
J2: A | K2: B | L2: C | M2: D | N2: E | O2: A | P2: B | Q2: C | R2: D | S2: E
A3: Min Coll | B3: 10th St | C3: Alabama Ave to Sheeler Ave | D3: CITY | E3: 411 | F3: 411 | G3: 2L | H3: E | I3: 30 | J3: 0 | K3: 0 | L3: 240 | M3: 490 | N3: 520 | O3: 0 | P3: 0 | Q3: 4700 | R3: 9600 | S3: 10100
A4: Min Coll | B4: 13th St | C4: Ocoee-Apopka Rd to Park Ave | D4: CITY | E4: 840 | F4: 840 | G4: 2L | H4: E | I4: 25 | J4: 0 | K4: 0 | L4: 240 | M4: 490 | N4: 520 | O4: 0 | P4: 0 | Q4: 4700 | R4: 9600 | S4: 10100
A5: Min Coll | B5: 13th St | C5: Park Ave to Apopka Blvd | D5: CITY | E5: 841 | F5: 841 | G5: 2L | H5: E | I5: 25 | J5: 0 | K5: 0 | L5: 240 | M5: 490 | N5: 520 | O5: 0 | P5: 0 | Q5: 4700 | R5: 9600 | S5: 10100
A6: Min Coll | B6: 2nd St (Monroe Ave) | C6: Central Ave to Park Ave | D6: CITY | E6: 401 | F6: 401 | G6: 2L | H6: D | I6: 30 | J6: 0 | K6: 0 | L6: 240 | M6: 490 | N6: 520 | O6: 0 | P6: 0 | Q6: 4700 | R6: 9600 | S6: 10100
A7: Min Coll | B7: 5th St | C7: Park Ave to Highland Ave | D7: CITY | E7: 403 | F7: 403 | G7: 2L | H7: D | I7: 30 | J7: 0 | K7: 0 | L7: 240 | M7: 490 | N7: 520 | O7: 0 | P7: 0 | Q7: 4700 | R7: 9600 | S7: 10100
A8: Min Coll | B8: 6th St | C8: Park Ave to Alabama Ave | D8: CITY | E8: 650 | F8: 650 | G8: 2L | H8: D | I8: 30 | J8: 0 | K8: 0 | L8: 240 | M8: 490 | N8: 520 | O8: 0 | P8: 0 | Q8: 4700 | R8: 9600 | S8: 10100
A9: Min Coll | B9: 6th St | C9: Alabama Ave to US 441 | D9: CITY | E9: 410 | F9: 410 | G9: 2L | H9: D | I9: 30 | J9: 0 | K9: 0 | L9: 240 | M9: 490 | N9: 520 | O9: 0 | P9: 0 | Q9: 4700 | R9: 9600 | S9: 10100
A10: Min Coll | B10: 8th St | C10: Park Ave to Highland Ave | D10: CITY | E10: 404 | F10: 404 | G10: 2L | H10: D | I10: 30 | J10: 0 | K10: 0 | L10: 240 | M10: 490 | N10: 520 | O10: 0 | P10: 0 | Q10: 4700 | R10: 9600 | S10: 10100
A11: Min Coll | B11: 9th St | C11: Central Ave to Park Ave | D11: CITY | E11: 333 | F11: 333 | G11: 2L | H11: E | I11: 30 | J11: 0 | K11: 0 | L11: 240 | M11: 490 | N11: 520 | O11: 0 | P11: 0 | Q11: 4700 | R11: 9600 | S11: 10100
A12: Min Coll | B12: Alabama Ave | C12: Monroe Ave to US 441 | D12: CITY | E12: 409 | F12: 409 | G12: 2L | H12: E | I12: 25 | J12: 0 | K12: 0 | L12: 240 | M12: 490 | N12: 520 | O12: 0 | P12: 0 | Q12: 4700 | R12: 9600 | S12: 10100
A13: Min Coll | B13: Appy Ln | C13: Plymouth-Sorrento Rd (CR 437) to Jason Dwelley Pkwy | D13: CITY | E13: 971 | F13: 971 | G13: 2L | H13: E | I13: 35 | J13: 0 | K13: 0 | L13: 330 | M13: 680 | N13: 720 | O13: 0 | P13: 0 | Q13: 6600 | R13: 13320 | S13: 14000
A14: Min Coll | B14: Binion Rd/Orange Ave | C14: Lakeview Dr to US 441 | D14: COUNTY | E14: 554 | F14: 404* | G14: 2L | H14: E | I14: 40 | J14: 0 | K14: 0 | L14: 830 | M14: 880 | N14: 880 | O14: 0 | P14: 0 | Q14: 16800 | R14: 17700 | S14: 17700
A15: Min Coll | B15: Binion Rd/Orange Ave | C15: Boy Scout Rd to Lakeview Dr | D15: COUNTY | E15: 553 | F15: (404, 327)* | G15: 2L | H15: E | I15: 40 | J15: 0 | K15: 0 | L15: 830 | M15: 880 | N15: 880 | O15: 0 | P15: 0 | Q15: 16800 | R15: 17700 | S15: 17700
A16: Min Coll | B16: Binion Rd/Orange Ave | C16: Ocoee-Apopka Rd to Harmon Rd | D16: COUNTY | E16: 28 | F16: 28* | G16: 2L | H16: E | I16: 55 | J16: 0 | K16: 0 | L16: 830 | M16: 880 | N16: 880 | O16: 0 | P16: 0 | Q16: 16800 | R16: 17700 | S16: 17700
A17: Min Coll | B17: Binion Rd/Orange Ave | C17: Harmon Rd to Boy Scout Rd | D17: CITY | E17: 673 | F17: 673 | G17: 2L | H17: E | I17: 55 | J17: 0 | K17: 0 | L17: 830 | M17: 880 | N17: 880 | O17: 0 | P17: 0 | Q17: 16800 | R17: 17700 | S17: 17700
A18: Min Coll | B18: Boy Scout Rd | C18: Binion Rd to Ocoee-Apopka Rd | D18: CITY | E18: 556 | F18: 556 | G18: 2L | H18: E | I18: 45 | J18: 0 | K18: 0 | L18: 750 | M18: 790 | N18: 790 | O18: 0 | P18: 0 | Q18: 15100 | R18: 15900 | S18: 15900
A19: Min Coll | B19: Bradshaw Rd | C19: US 441 to Ocoee-Apopka Rd | D19: CITY | E19: 557 | F19: 557 | G19: 2L | H19: E | I19: 45 | J19: 0 | K19: 0 | L19: 750 | M19: 790 | N19: 790 | O19: 0 | P19: 0 | Q19: 15100 | R19: 15900 | S19: 15900
A20: Min Art | B20: CR 424 (Alabama Ave/Apopka Blvd) | C20: Hiawassee Rd to Overland Rd | D20: COUNTY | E20: 33.1 | F20: 33* | G20: 2L | H20: E | I20: 35 | J20: 0 | K20: 0 | L20: 370 | M20: 750 | N20: 800 | O20: 0 | P20: 0 | Q20: 7300 | R20: 14800 | S20: 15600
A21: Min Art | B21: CR 424 (Alabama Ave/Apopka Blvd) | C21: 8th St to Sheeler Rd | D21: COUNTY | E21: 651 | F21: 1008* | G21: 2L | H21: E | I21: 45 | J21: 0 | K21: 0 | L21: 830 | M21: 880 | N21: 880 | O21: 0 | P21: 0 | Q21: 16800 | R21: 17700 | S21: 17700
A22: Min Art | B22: CR 424 (Alabama Ave/Apopka Blvd) | C22: Overland Rd to US 441 | D22: CITY | E22: 671 | F22: 671 | G22: 2L | H22: E | I22: 35 | J22: 0 | K22: 0 | L22: 370 | M22: 750 | N22: 800 | O22: 0 | P22: 0 | Q22: 7300 | R22: 14800 | S22: 15600
A23: Min Art | B23: CR 424 (Alabama Ave/Apopka Blvd) | C23: Lakeville Rd to Hiawassee Rd | D23: CITY | E23: 658 | F23: 658 | G23: 3L | H23: E | I23: 40 | J23: 0 | K23: 0 | L23: 870 | M23: 920 | N23: 920 | O23: 0 | P23: 0 | Q23: 17600 | R23: 18600 | S23: 18600
A24: Min Art | B24: CR 424 (Alabama Ave/Apopka Blvd) | C24: Sheeler Rd to Lakeville Rd | D24: COUNTY | E24: 653 | F24: 7033* | G24: 2L | H24: E | I24: 40 | J24: 0 | K24: 0 | L24: 830 | M24: 880 | N24: 880 | O24: 0 | P24: 0 | Q24: 16800 | R24: 17700 | S24: 17700
A25: Min Art | B25: CR 424 (Alabama Ave/Apopka Blvd) | C25: US 441 to 8th St | D25: CITY | E25: 670 | F25: 670 | G25: 2L | H25: E | I25: 45 | J25: 0 | K25: 0 | L25: 370 | M25: 750 | N25: 800 | O25: 0 | P25: 0 | Q25: 7300 | R25: 14800 | S25: 15600
A26: Min Art | B26: CR 435 (Rock Spring Rd/Park Ave/Clarcona Rd) | C26: Keene Rd to McCormick Rd | D26: COUNTY | E26: 565 | F26: (32, 7004)* | G26: 2L | H26: E | I26: 45 | J26: 0 | K26: 0 | L26: 830 | M26: 880 | N26: 880 | O26: 0 | P26: 0 | Q26: 16800 | R26: 17700 | S26: 17700
A27: Min Art | B27: CR 435 (Rock Spring Rd/Park Ave/Clarcona Rd) | C27: M. Gladden Blvd to Cleveland St | D27: COUNTY | E27: 328.1 | F27: 328* | G27: 2L | H27: E | I27: 30 | J27: 0 | K27: 0 | L27: 370 | M27: 750 | N27: 800 | O27: 0 | P27: 0 | Q27: 7300 | R27: 14800 | S27: 15600
A28: Min Art | B28: CR 435 (Rock Spring Rd/Park Ave/Clarcona Rd) | C28: Votaw Rd to Orange St | D28: COUNTY | E28: 426 | F28: 426* | G28: 5L | H28: E | I28: 35 | J28: 0 | K28: 0 | L28: 730 | M28: 1630 | N28: 1700 | O28: 0 | P28: 0 | Q28: 14500 | R28: 32400 | S28: 33800
A29: Min Art | B29: CR 435 (Rock Spring Rd/Park Ave/Clarcona Rd) | C29: Welch Rd to Sandpiper Rd | D29: COUNTY | E29: 21 | F29: 21* | G29: 5L | H29: E | I29: 45 | J29: 0 | K29: 0 | L29: 1910 | M29: 2000 | N29: 2000 | O29: 0 | P29: 0 | Q29: 37900 | R29: 39800 | S29: 39800
A30: Min Art | B30: CR 435 (Rock Spring Rd/Park Ave/Clarcona Rd) | C30: Ponkan Rd to Welch Rd | D30: COUNTY | E30: 19 | F30: 19* | G30: 5L | H30: E | I30: 45 | J30: 0 | K30: 0 | L30: 1910 | M30: 2000 | N30: 2000 | O30: 0 | P30: 0 | Q30: 37900 | R30: 39800 | S30: 39800
A31: Min Art | B31: CR 435 (Rock Spring Rd/Park Ave/Clarcona Rd) | C31: McCormick Rd to Clarcona-Ocoee Rd | D31: CITY | E31: 7004 | F31: 7004 | G31: 2L | H31: E | I31: 45 | J31: 0 | K31: 0 | L31: 830 | M31: 880 | N31: 880 | O31: 0 | P31: 0 | Q31: 16800 | R31: 17700 | S31: 17700
A32: Min Art | B32: CR 435 (Rock Spring Rd/Park Ave/Clarcona Rd) | C32: Sandpiper Rd to Votaw Rd | D32: CITY | E32: 516 | F32: 516 | G32: 5L | H32: E | I32: 35 | J32: 0 | K32: 0 | L32: 730 | M32: 1630 | N32: 1700 | O32: 0 | P32: 0 | Q32: 14500 | R32: 32400 | S32: 33800
A33: Min Art | B33: CR 435 (Rock Spring Rd/Park Ave/Clarcona Rd) | C33: US 441 to M. Gladden Blvd | D33: CITY | E33: 563 | F33: 563 | G33: 2L | H33: E | I33: 30 | J33: 0 | K33: 0 | L33: 370 | M33: 750 | N33: 800 | O33: 0 | P33: 0 | Q33: 7300 | R33: 14800 | S33: 15600
A34: Min Art | B34: CR 435 (Rock Spring Rd/Park Ave/Clarcona Rd) | C34: Orange St to US 441 | D34: CITY | E34: 580 | F34: 580 | G34: 5L | H34: E | I34: 35 | J34: 0 | K34: 0 | L34: 730 | M34: 1630 | N34: 1700 | O34: 0 | P34: 0 | Q34: 14500 | R34: 32400 | S34: 33800
A35: Min Art | B35: CR 435 (Rock Spring Rd/Park Ave/Clarcona Rd) | C35: Cleveland St to Keene Rd | D35: COUNTY | E35: 564 | F35: 7005* | G35: 2L | H35: E | I35: 45 | J35: 0 | K35: 0 | L35: 830 | M35: 880 | N35: 880 | O35: 0 | P35: 0 | Q35: 16800 | R35: 17700 | S35: 17700
A36: Min Art | B36: CR 435 (Rock Spring Rd/Park Ave/Clarcona Rd) | C36: Kelly Park Rd to Ponkan Rd | D36: COUNTY | E36: 18.1 | F36: 18* | G36: 4LD | H36: E | I36: 45 | J36: 0 | K36: 0 | L36: 1910 | M36: 2000 | N36: 2000 | O36: 0 | P36: 0 | Q36: 37900 | R36: 39800 | S36: 39800
A37: Min Art | B37: CR 437A (Ocoee-Apopka Rd/Michael Gladden Blvd/Central Ave) | C37: Harmon Rd to Bradshaw Rd | D37: COUNTY | E37: 27 | F37: 27* | G37: 2L | H37: E | I37: 45 | J37: 0 | K37: 0 | L37: 830 | M37: 880 | N37: 880 | O37: 0 | P37: 0 | Q37: 16800 | R37: 17700 | S37: 17700
A38: Min Art | B38: CR 437A (Ocoee-Apopka Rd/Michael Gladden Blvd/Central Ave) | C38: Bradshaw Rd to Park Ave | D38: COUNTY | E38: 7083 | F38: 7083* | G38: 2L | H38: E | I38: 35 | J38: 0 | K38: 0 | L38: 370 | M38: 750 | N38: 800 | O38: 0 | P38: 0 | Q38: 7300 | R38: 14800 | S38: 15600
A39: Min Art | B39: CR 437A (Ocoee-Apopka Rd/Michael Gladden Blvd/Central Ave) | C39: Alston Bay Blvd to Harmon Rd | D39: COUNTY | E39: 559 | F39: (27, 29)* | G39: 4LD | H39: E | I39: 45 | J39: 0 | K39: 0 | L39: 830 | M39: 880 | N39: 880 | O39: 0 | P39: 0 | Q39: 16800 | R39: 17700 | S39: 17700
A40: Min Art | B40: CR 437A (Ocoee-Apopka Rd/Michael Gladden Blvd/Central Ave) | C40: Keene Rd to Alston Bay Blvd | D40: CITY | E40: 29 | F40: 29 | G40: 2L | H40: E | I40: 45 | J40: 0 | K40: 0 | L40: 830 | M40: 880 | N40: 880 | O40: 0 | P40: 0 | Q40: 16800 | R40: 17700 | S40: 17700
...

Sheet LOS
A1: Class | B1: Roadway | C1: Segment | D1: Source | E1: 2022 Station | F1: 2025 Station | G1: Lns | H1: LOS Std | I1: Speed Limit | J1: Daily | L1: AM Peak Hour (7-9 am) | R1: PM Peak Hour (4-6 pm)
J2: Volume | K2: LOS | L2: NB/EB | M2: SB/WB | N2: Time | O2: K | P2: D | Q2: LOS | R2: NB/EB | S2: SB/WB | T2: Time | U2: K | V2: D | W2: LOS
A3: Min Coll | B3: 10th St | C3: Alabama Ave to Sheeler Ave | D3: CITY | E3: 411 | F3: 411 | G3: 2L | H3: E | I3: 30 | J3: 467 | K3: C | L3: 18 | M3: 19 | N3: 07:00 | O3: 0.08 | P3: 0.51 | Q3: C | R3: 18 | S3: 18 | T3: 16:00 | U3: 0.08 | V3: 0.5 | W3: C
A4: Min Coll | B4: 13th St | C4: Ocoee-Apopka Rd to Park Ave | D4: CITY | E4: 840 | F4: 840 | G4: 2L | H4: E | I4: 25 | J4: 3017 | K4: C | L4: 101 | M4: 130 | N4: 08:00 | O4: 0.08 | P4: 0.56 | Q4: C | R4: 137 | S4: 120 | T4: 17:00 | U4: 0.09 | V4: 0.53 | W4: C
A5: Min Coll | B5: 13th St | C5: Park Ave to Apopka Blvd | D5: CITY | E5: 841 | F5: 841 | G5: 2L | H5: E | I5: 25 | J5: 3788 | K5: C | L5: 150 | M5: 88 | N5: 07:00 | O5: 0.06 | P5: 0.63 | Q5: C | R5: 129 | S5: 196 | T5: 17:00 | U5: 0.09 | V5: 0.6 | W5: C
A6: Min Coll | B6: 2nd St (Monroe Ave) | C6: Central Ave to Park Ave | D6: CITY | E6: 401 | F6: 401 | G6: 2L | H6: D | I6: 30 | J6: 897 | K6: C | L6: 31 | M6: 32 | N6: 08:00 | O6: 0.07 | P6: 0.51 | Q6: C | R6: 40 | S6: 50 | T6: 16:00 | U6: 0.1 | V6: 0.56 | W6: C
A7: Min Coll | B7: 5th St | C7: Park Ave to Highland Ave | D7: CITY | E7: 403 | F7: 403 | G7: 2L | H7: D | I7: 30 | J7: 1778 | K7: C | L7: 113 | M7: 96 | N7: 07:00 | O7: 0.12 | P7: 0.54 | Q7: C | R7: 83 | S7: 63 | T7: 17:00 | U7: 0.08 | V7: 0.57 | W7: C
A8: Min Coll | B8: 6th St | C8: Park Ave to Alabama Ave | D8: CITY | E8: 650 | F8: 650 | G8: 2L | H8: D | I8: 30 | J8: 2283 | K8: C | L8: 48 | M8: 115 | N8: 07:00 | O8: 0.07 | P8: 0.71 | Q8: C | R8: 69 | S8: 165 | T8: 16:00 | U8: 0.1 | V8: 0.71 | W8: C
A9: Min Coll | B9: 6th St | C9: Alabama Ave to US 441 | D9: CITY | E9: 410 | F9: 410 | G9: 2L | H9: D | I9: 30 | J9: 1435 | K9: C | L9: 50 | M9: 57 | N9: 07:00 | O9: 0.07 | P9: 0.53 | Q9: C | R9: 57 | S9: 87 | T9: 17:00 | U9: 0.1 | V9: 0.6 | W9: C
A10: Min Coll | B10: 8th St | C10: Park Ave to Highland Ave | D10: CITY | E10: 404 | F10: 404 | G10: 2L | H10: D | I10: 30 | J10: 3069 | K10: C | L10: 86 | M10: 92 | N10: 07:00 | O10: 0.06 | P10: 0.52 | Q10: C | R10: 127 | S10: 164 | T10: 16:00 | U10: 0.09 | V10: 0.56 | W10: C
A11: Min Coll | B11: 9th St | C11: Central Ave to Park Ave | D11: CITY | E11: 333 | F11: 333 | G11: 2L | H11: E | I11: 30 | J11: 3797 | K11: C | L11: 134 | M11: 114 | N11: 08:00 | O11: 0.07 | P11: 0.54 | Q11: C | R11: 181 | S11: 130 | T11: 17:00 | U11: 0.08 | V11: 0.58 | W11: C
A12: Min Coll | B12: Alabama Ave | C12: Monroe Ave to US 441 | D12: CITY | E12: 409 | F12: 409 | G12: 2L | H12: E | I12: 25 | J12: 297 | K12: C | L12: 9 | M12: 8 | N12: 07:00 | O12: 0.06 | P12: 0.53 | Q12: C | R12: 20 | S12: 7 | T12: 16:00 | U12: 0.09 | V12: 0.74 | W12: C
A13: Min Coll | B13: Appy Ln | C13: Plymouth-Sorrento Rd (CR 437) to Jason Dwelley Pkwy | D13: CITY | E13: 971 | F13: 971 | G13: 2L | H13: E | I13: 35 | J13: 1224 | K13: C | L13: 89 | M13: 95 | N13: 08:00 | O13: 0.15 | P13: 0.52 | Q13: C | R13: 49 | S13: 36 | T13: 17:00 | U13: 0.07 | V13: 0.58 | W13: C
A14: Min Coll | B14: Binion Rd/Orange Ave | C14: Lakeview Dr to US 441 | D14: COUNTY | E14: 554 | F14: 404* | G14: 2L | H14: E | I14: 40 | J14: 6029 | K14: C | L14: 239 | M14: 348 | N14: 0.30208333 | O14: 0.1 | P14: 0.59 | Q14: C | R14: 320 | S14: 230 | T14: 0.6875 | U14: 0.09 | V14: 0.58 | W14: C
A15: Min Coll | B15: Binion Rd/Orange Ave | C15: Boy Scout Rd to Lakeview Dr | D15: COUNTY | E15: 553 | F15: (404, 327)* | G15: 2L | H15: E | I15: 40 | J15: 11510 | K15: C | L15: 414 | M15: 565 | N15: 0.29166667 | O15: 0.09 | P15: 0.58 | Q15: C | R15: 566 | S15: 447 | T15: 0.61458333 | U15: 0.09 | V15: 0.56 | W15: C
A16: Min Coll | B16: Binion Rd/Orange Ave | C16: Ocoee-Apopka Rd to Harmon Rd | D16: COUNTY | E16: 28 | F16: 28* | G16: 2L | H16: E | I16: 55 | J16: 7257 | K16: C | L16: 357 | M16: 216 | N16: 0.29166667 | O16: 0.08 | P16: 0.62 | Q16: C | R16: 308 | S16: 367 | T16: 0.61458333 | U16: 0.09 | V16: 0.54 | W16: C
A17: Min Coll | B17: Binion Rd/Orange Ave | C17: Harmon Rd to Boy Scout Rd | D17: CITY | E17: 673 | F17: 673 | G17: 2L | H17: E | I17: 55 | J17: 9014 | K17: C | L17: 314 | M17: 484 | N17: 07:00 | O17: 0.09 | P17: 0.61 | Q17: C | R17: 376 | S17: 341 | T17: 17:00 | U17: 0.08 | V17: 0.52 | W17: C
A18: Min Coll | B18: Boy Scout Rd | C18: Binion Rd to Ocoee-Apopka Rd | D18: CITY | E18: 556 | F18: 556 | G18: 2L | H18: E | I18: 45 | J18: 2992 | K18: C | L18: 111 | M18: 111 | N18: 08:00 | O18: 0.07 | P18: 0.5 | Q18: C | R18: 129 | S18: 133 | T18: 16:00 | U18: 0.09 | V18: 0.51 | W18: C
A19: Min Coll | B19: Bradshaw Rd | C19: US 441 to Ocoee-Apopka Rd | D19: CITY | E19: 557 | F19: 557 | G19: 2L | H19: E | I19: 45 | J19: 8963 | K19: C | L19: 347 | M19: 277 | N19: 07:00 | O19: 0.07 | P19: 0.56 | Q19: C | R19: 405 | S19: 292 | T19: 17:00 | U19: 0.08 | V19: 0.58 | W19: C
A20: Min Art | B20: CR 424 (Alabama Ave/Apopka Blvd) | C20: Hiawassee Rd to Overland Rd | D20: COUNTY | E20: 33.1 | F20: 33* | G20: 2L | H20: E | I20: 35 | J20: 7400 | K20: D | L20: 440 | M20: 160 | N20: 08:00 | O20: 0.08 | P20: 0.73 | Q20: D | R20: 200 | S20: 350 | T20: 17:00 | U20: 0.07 | V20: 0.64 | W20: C
A21: Min Art | B21: CR 424 (Alabama Ave/Apopka Blvd) | C21: 8th St to Sheeler Rd | D21: COUNTY | E21: 651 | F21: 1008* | G21: 2L | H21: E | I21: 45 | J21: 5068 | K21: C | L21: 166 | M21: 223 | N21: 07:00 | O21: 0.08 | P21: 0.57 | Q21: C | R21: 212 | S21: 280 | T21: 17:00 | U21: 0.1 | V21: 0.57 | W21: C
A22: Min Art | B22: CR 424 (Alabama Ave/Apopka Blvd) | C22: Overland Rd to US 441 | D22: CITY | E22: 671 | F22: 671 | G22: 2L | H22: E | I22: 35 | J22: 6157 | K22: C | L22: 259 | M22: 216 | N22: 0.30208333 | O22: 0.08 | P22: 0.55 | Q22: C | R22: 282 | S22: 157 | T22: 0.69791667 | U22: 0.07 | V22: 0.64 | W22: C
A23: Min Art | B23: CR 424 (Alabama Ave/Apopka Blvd) | C23: Lakeville Rd to Hiawassee Rd | D23: CITY | E23: 658 | F23: 658 | G23: 3L | H23: E | I23: 40 | J23: 12357 | K23: C | L23: 491 | M23: 333 | N23: 0.30208333 | O23: 0.07 | P23: 0.6 | Q23: C | R23: 421 | S23: 667 | T23: 0.6875 | U23: 0.09 | V23: 0.61 | W23: C
A24: Min Art | B24: CR 424 (Alabama Ave/Apopka Blvd) | C24: Sheeler Rd to Lakeville Rd | D24: COUNTY | E24: 653 | F24: 7033* | G24: 2L | H24: E | I24: 40 | J24: 9481 | K24: C | L24: 364 | M24: 306 | N24: 0.29166667 | O24: 0.07 | P24: 0.54 | Q24: C | R24: 405 | S24: 465 | T24: 0.70833333 | U24: 0.09 | V24: 0.53 | W24: C
A25: Min Art | B25: CR 424 (Alabama Ave/Apopka Blvd) | C25: US 441 to 8th St | D25: CITY | E25: 670 | F25: 670 | G25: 2L | H25: E | I25: 45 | J25: 2343 | K25: C | L25: 42 | M25: 80 | N25: 08:00 | O25: 0.05 | P25: 0.66 | Q25: C | R25: 97 | S25: 136 | T25: 17:00 | U25: 0.1 | V25: 0.58 | W25: C
A26: Min Art | B26: CR 435 (Rock Spring Rd/Park Ave/Clarcona Rd) | C26: Keene Rd to McCormick Rd | D26: COUNTY | E26: 565 | F26: (32, 7004)* | G26: 2L | H26: E | I26: 45 | J26: 34702 | K26: F | L26: 1239 | M26: 1353 | N26: 07:00 | O26: 0.07 | P26: 0.52 | Q26: F | R26: 1445 | S26: 1556 | T26: 17:00 | U26: 0.09 | V26: 0.52 | W26: F
A27: Min Art | B27: CR 435 (Rock Spring Rd/Park Ave/Clarcona Rd) | C27: M. Gladden Blvd to Cleveland St | D27: COUNTY | E27: 328.1 | F27: 328* | G27: 2L | H27: E | I27: 30 | J27: 10804 | K27: D | L27: 361 | M27: 353 | N27: 07:00 | O27: 0.07 | P27: 0.51 | Q27: C | R27: 436 | S27: 389 | T27: 16:00 | U27: 0.08 | V27: 0.53 | W27: D
A28: Min Art | B28: CR 435 (Rock Spring Rd/Park Ave/Clarcona Rd) | C28: Votaw Rd to Orange St | D28: COUNTY | E28: 426 | F28: 426* | G28: 5L | H28: E | I28: 35 | J28: 22637 | K28: D | L28: 651 | M28: 988 | N28: 0.28125 | O28: 0.07 | P28: 0.6 | Q28: D | R28: 1030 | S28: 793 | T28: 0.69791667 | U28: 0.08 | V28: 0.57 | W28: D
A29: Min Art | B29: CR 435 (Rock Spring Rd/Park Ave/Clarcona Rd) | C29: Welch Rd to Sandpiper Rd | D29: COUNTY | E29: 21 | F29: 21* | G29: 5L | H29: E | I29: 45 | J29: 25374 | K29: C | L29: 1384 | M29: 698 | N29: 0.29166667 | O29: 0.08 | P29: 0.66 | Q29: C | R29: 954 | S29: 1359 | T29: 0.70833333 | U29: 0.09 | V29: 0.59 | W29: C
A30: Min Art | B30: CR 435 (Rock Spring Rd/Park Ave/Clarcona Rd) | C30: Ponkan Rd to Welch Rd | D30: COUNTY | E30: 19 | F30: 19* | G30: 5L | H30: E | I30: 45 | J30: 24553 | K30: C | L30: 754 | M30: 1179 | N30: 0.28125 | O30: 0.08 | P30: 0.61 | Q30: C | R30: 1361 | S30: 906 | T30: 0.70833333 | U30: 0.09 | V30: 0.6 | W30: C
A31: Min Art | B31: CR 435 (Rock Spring Rd/Park Ave/Clarcona Rd) | C31: McCormick Rd to Clarcona-Ocoee Rd | D31: CITY | E31: 7004 | F31: 7004 | G31: 2L | H31: E | I31: 45 | J31: 15230 | K31: C | L31: 505 | M31: 588 | N31: 0.33333333 | O31: 0.07 | P31: 0.54 | Q31: C | R31: 667 | S31: 540 | T31: 0.71875 | U31: 0.08 | V31: 0.55 | W31: C
A32: Min Art | B32: CR 435 (Rock Spring Rd/Park Ave/Clarcona Rd) | C32: Sandpiper Rd to Votaw Rd | D32: CITY | E32: 516 | F32: 516 | G32: 5L | H32: E | I32: 35 | J32: 22569 | K32: D | L32: 605 | M32: 1076 | N32: 0.30208333 | O32: 0.07 | P32: 0.64 | Q32: D | R32: 1126 | S32: 749 | T32: 0.6875 | U32: 0.08 | V32: 0.6 | W32: D
A33: Min Art | B33: CR 435 (Rock Spring Rd/Park Ave/Clarcona Rd) | C33: US 441 to M. Gladden Blvd | D33: CITY | E33: 563 | F33: 563 | G33: 2L | H33: E | I33: 30 | J33: 11434 | K33: D | L33: 428 | M33: 296 | N33: 0.29166667 | O33: 0.06 | P33: 0.59 | Q33: D | R33: 493 | S33: 396 | T33: 0.6875 | U33: 0.08 | V33: 0.55 | W33: D
A34: Min Art | B34: CR 435 (Rock Spring Rd/Park Ave/Clarcona Rd) | C34: Orange St to US 441 | D34: CITY | E34: 580 | F34: 580 | G34: 5L | H34: E | I34: 35 | J34: 25032 | K34: D | L34: 872 | M34: 941 | N34: 0.29166667 | O34: 0.07 | P34: 0.52 | Q34: D | R34: 994 | S34: 861 | T34: 0.69791667 | U34: 0.07 | V34: 0.54 | W34: D
A35: Min Art | B35: CR 435 (Rock Spring Rd/Park Ave/Clarcona Rd) | C35: Cleveland St to Keene Rd | D35: COUNTY | E35: 564 | F35: 7005* | G35: 2L | H35: E | I35: 45 | J35: 10179 | K35: C | L35: 337 | M35: 377 | N35: 07:00 | O35: 0.07 | P35: 0.53 | Q35: C | R35: 416 | S35: 403 | T35: 16:00 | U35: 0.08 | V35: 0.51 | W35: C
A36: Min Art | B36: CR 435 (Rock Spring Rd/Park Ave/Clarcona Rd) | C36: Kelly Park Rd to Ponkan Rd | D36: COUNTY | E36: 18.1 | F36: 18* | G36: 4LD | H36: E | I36: 45 | J36: 16631 | K36: C | L36: 469 | M36: 832 | N36: 08:00 | O36: 0.08 | P36: 0.64 | Q36: C | R36: 905 | S36: 655 | T36: 17:00 | U36: 0.09 | V36: 0.58 | W36: C
A37: Min Art | B37: CR 437A (Ocoee-Apopka Rd/Michael Gladden Blvd/Central Ave) | C37: Harmon Rd to Bradshaw Rd | D37: COUNTY | E37: 27 | F37: 27* | G37: 2L | H37: E | I37: 45 | J37: 15272 | K37: C | L37: 568 | M37: 600 | N37: 08:00 | O37: 0.08 | P37: 0.51 | Q37: C | R37: 598 | S37: 1933 | T37: 17:00 | U37: 0.17 | V37: 0.76 | W37: F
A38: Min Art | B38: CR 437A (Ocoee-Apopka Rd/Michael Gladden Blvd/Central Ave) | C38: Bradshaw Rd to Park Ave | D38: COUNTY | E38: 7083 | F38: 7083* | G38: 2L | H38: E | I38: 35 | J38: 8924 | K38: D | L38: 352 | M38: 308 | N38: 0.3125 | O38: 0.07 | P38: 0.53 | Q38: C | R38: 413 | S38: 345 | T38: 0.61458333 | U38: 0.08 | V38: 0.54 | W38: D
A39: Min Art | B39: CR 437A (Ocoee-Apopka Rd/Michael Gladden Blvd/Central Ave) | C39: Alston Bay Blvd to Harmon Rd | D39: COUNTY | E39: 559 | F39: (27, 29)* | G39: 4LD | H39: E | I39: 45 | J39: 29461 | K39: F | L39: 1170 | M39: 1187 | N39: 0.3125 | O39: 0.08 | P39: 0.5 | Q39: F | R39: 1175 | S39: 2553 | T39: 0.61458333 | U39: 0.13 | V39: 0.68 | W39: F
A40: Min Art | B40: CR 437A (Ocoee-Apopka Rd/Michael Gladden Blvd/Central Ave) | C40: Keene Rd to Alston Bay Blvd | D40: CITY | E40: 29 | F40: 29 | G40: 2L | H40: E | I40: 45 | J40: 15179 | K40: C | L40: 629 | M40: 573 | N40: 0.30208333 | O40: 0.08 | P40: 0.52 | Q40: C | R40: 603 | S40: 554 | T40: 0.70833333 | U40: 0.08 | V40: 0.52 | W40: C
...

Sheet Historical ADT
A1: Class | B1: Roadway | C1: Segment | D1: Source | E1: 2022 Station | F1: 2025 Station | G1: Historical Daily Volumes
G2: 2025 | H2: 2024 | I2: 2023 | J2: 2022 | K2: 2021(1) | L2: 2020 | M2: 2019 | N2: 2018 | O2: 2017 | P2: 2016 | Q2: 2015 | R2: 2014 | S2: 2013 | T2: 2012 | U2: 2011 | V2: 2010 | W2: 2009 | X2: 2008 | Y2: 2007 | Z2: 2006 | AA2: 2005 | AB2: 2004 | AC2: 2003 | AD2: 2002 | AE2: 2001 | AF2: 2000 | AG2: 1999 | AH2: 1998 | AI2: 1997 | AJ2: 1995 | AK2: 1994 | AL2: 1993 | AM2: 88 / 89
A3: Min Coll | B3: 10th St | C3: Alabama Ave to Sheeler Ave | D3: CITY | E3: 411 | F3: 411 | G3: 467 | H3: 469 | I3: 475 | J3: 471 | K3: 485 | L3: 500 | M3: 498 | N3: 502 | O3: 562 | P3: 447 | Q3: 482 | R3: 467 | S3: 259 | T3: 532 | U3: 410 | V3: 215 | W3: --- | X3: --- | Y3: --- | Z3: --- | AA3: --- | AB3: --- | AC3: --- | AD3: --- | AE3: --- | AF3: --- | AG3: --- | AH3: --- | AI3: --- | AJ3: --- | AK3: --- | AL3: --- | AM3: ---
A4: Min Coll | B4: 13th St | C4: Ocoee-Apopka Rd to Park Ave | D4: CITY | E4: 840 | F4: 840 | G4: 3017 | H4: 2871 | I4: 2771 | J4: 2697 | K4: 2488 | L4: 2278 | M4: 2570 | N4: 2553 | O4: 2428 | P4: 3285 | Q4: 2307 | R4: 2417 | S4: 1599 | T4: 1820 | U4: 2432 | V4: --- | W4: --- | X4: --- | Y4: --- | Z4: --- | AA4: --- | AB4: --- | AC4: --- | AD4: --- | AE4: --- | AF4: --- | AG4: --- | AH4: --- | AI4: --- | AJ4: --- | AK4: --- | AL4: --- | AM4: ---
A5: Min Coll | B5: 13th St | C5: Park Ave to Apopka Blvd | D5: CITY | E5: 841 | F5: 841 | G5: 3788 | H5: 3692 | I5: 3642 | J5: 3639 | K5: 3450 | L5: 3260 | M5: 3677 | N5: 3724 | O5: 3414 | P5: 3384 | Q5: 2862 | R5: 2430 | S5: 2057 | T5: 2480 | U5: 2491 | V5: --- | W5: --- | X5: --- | Y5: --- | Z5: --- | AA5: --- | AB5: --- | AC5: --- | AD5: --- | AE5: --- | AF5: --- | AG5: --- | AH5: --- | AI5: --- | AJ5: --- | AK5: --- | AL5: --- | AM5: ---
A6: Min Coll | B6: 2nd St (Monroe Ave) | C6: Central Ave to Park Ave | D6: CITY | E6: 401 | F6: 401 | G6: 897 | H6: 947 | I6: 994 | J6: 1025 | K6: 1100 | L6: 1174 | M6: 1147 | N6: 1098 | O6: 1061 | P6: 1040 | Q6: 960 | R6: 959 | S6: 1267 | T6: 1282 | U6: 1160 | V6: 997 | W6: --- | X6: --- | Y6: --- | Z6: --- | AA6: --- | AB6: --- | AC6: --- | AD6: --- | AE6: --- | AF6: --- | AG6: --- | AH6: --- | AI6: --- | AJ6: --- | AK6: --- | AL6: --- | AM6: ---
A7: Min Coll | B7: 5th St | C7: Park Ave to Highland Ave | D7: CITY | E7: 403 | F7: 403 | G7: 1778 | H7: 2708 | I7: 2836 | J7: 3921 | K7: 3818 | L7: 3714 | M7: 1978 | N7: 1014 | O7: 594 | P7: 759 | Q7: 704 | R7: 598 | S7: 714 | T7: 718 | U7: 515 | V7: 1908 | W7: --- | X7: --- | Y7: --- | Z7: --- | AA7: --- | AB7: --- | AC7: --- | AD7: --- | AE7: --- | AF7: --- | AG7: --- | AH7: --- | AI7: --- | AJ7: --- | AK7: --- | AL7: --- | AM7: ---
A8: Min Coll | B8: 6th St | C8: Park Ave to Alabama Ave | D8: CITY | E8: 650 | F8: 650 | G8: 2283 | H8: 3126 | I8: 3084 | J8: 4585 | K8: 3556 | L8: 2528 | M8: 2137 | N8: 2535 | O8: 2209 | P8: 2752 | Q8: 1963 | R8: 2029 | S8: 1895 | T8: 2045 | U8: 1824 | V8: 2223 | W8: 2824 | X8: 3284 | Y8: 3628 | Z8: 3633 | AA8: 2996 | AB8: 3135 | AC8: 3114 | AD8: 2172 | AE8: 2803 | AF8: 2101 | AG8: 2450 | AH8: 2748 | AI8: 2126 | AJ8: 2565 | AK8: 2707 | AL8: 2623 | AM8: 1549
A9: Min Coll | B9: 6th St | C9: Alabama Ave to US 441 | D9: CITY | E9: 410 | F9: 410 | G9: 1435 | H9: 1848 | I9: 1699 | J9: 2560 | K9: 1674 | L9: 787 | M9: CST. | N9: 693 | O9: 345 | P9: 544 | Q9: 559 | R9: 599 | S9: 609 | T9: 618 | U9: 606 | V9: 681 | W9: --- | X9: --- | Y9: --- | Z9: --- | AA9: --- | AB9: --- | AC9: --- | AD9: --- | AE9: --- | AF9: --- | AG9: --- | AH9: --- | AI9: --- | AJ9: --- | AK9: --- | AL9: --- | AM9: ---
A10: Min Coll | B10: 8th St | C10: Park Ave to Highland Ave | D10: CITY | E10: 404 | F10: 404 | G10: 3069 | H10: 4231 | I10: 4097 | J10: 6389 | K10: 4559 | L10: 2730 | M10: 2664 | N10: 2508 | O10: 2534 | P10: 2787 | Q10: 2170 | R10: 2601 | S10: 2622 | T10: 2497 | U10: 2374 | V10: 2548 | W10: --- | X10: --- | Y10: --- | Z10: --- | AA10: --- | AB10: --- | AC10: --- | AD10: --- | AE10: --- | AF10: --- | AG10: --- | AH10: --- | AI10: --- | AJ10: --- | AK10: --- | AL10: --- | AM10: ---
A11: Min Coll | B11: 9th St | C11: Central Ave to Park Ave | D11: CITY | E11: 333 | F11: 333 | G11: 3797 | H11: 4081 | I11: 4264 | J11: 4461 | K11: 4773 | L11: 5086 | M11: 4661 | N11: 4049 | O11: 3954 | P11: 3998 | Q11: 3343 | R11: 3116 | S11: 3059 | T11: 2908 | U11: 2572 | V11: 2784 | W11: 2729 | X11: 3049 | AA11: 3529 | AB11: 3298 | AC11: 4198 | AH11: 3723 | AI11: 3366 | AJ11: --- | AK11: --- | AL11: --- | AM11: ---
A12: Min Coll | B12: Alabama Ave | C12: Monroe Ave to US 441 | D12: CITY | E12: 409 | F12: 409 | G12: 297 | H12: 336 | I12: 353 | J12: 366 | K12: 422 | L12: 479 | M12: 336 | N12: 670 | O12: 786 | P12: 1003 | Q12: 362 | R12: 367 | S12: 444 | T12: 380 | U12: 329 | V12: 261 | W12: --- | X12: --- | Y12: --- | Z12: --- | AA12: --- | AB12: --- | AC12: --- | AD12: --- | AE12: --- | AF12: --- | AG12: --- | AH12: --- | AI12: --- | AJ12: --- | AK12: --- | AL12: --- | AM12: ---
A13: Min Coll | B13: Appy Ln | C13: Plymouth-Sorrento Rd (CR 437) to Jason Dwelley Pkwy | D13: CITY | E13: 971 | F13: 971 | G13: 1224 | H13: 1328 | I13: 1297 | J13: 1513 | K13: 1315 | L13: 1116 | M13: 1070 | N13: 903 | O13: 771 | P13: 900 | Q13: 689 | R13: 555 | S13: 550 | T13: 271 | U13: 272 | V13: 227 | W13: 265 | X13: --- | Y13: --- | Z13: --- | AA13: --- | AB13: --- | AC13: --- | AD13: --- | AE13: --- | AF13: --- | AG13: --- | AH13: --- | AI13: --- | AJ13: --- | AK13: --- | AL13: --- | AM13: ---
A14: Min Coll | B14: Binion Rd/Orange Ave | C14: Lakeview Dr to US 441 | D14: COUNTY | E14: 554 | F14: 404* | G14: 6099 | H14: 5661 | I14: 5482 | J14: 5371 | K14: 5035 | L14: 4698 | M14: 4935 | N14: 4423 | O14: 4268 | P14: 3967 | Q14: 4009 | R14: 3590 | S14: 3178 | T14: 4416 | U14: 3611 | V14: 4191 | W14: 4399 | X14: 3929 | Y14: 4317 | Z14: 3861 | AA14: 3430 | AB14: 3683 | AC14: 3862 | AD14: 3948 | AE14: 3507 | AF14: 3806 | AG14: 6668 | AH14: 5469 | AI14: 4534 | AJ14: --- | AK14: --- | AL14: --- | AM14: ---
A15: Min Coll | B15: Binion Rd/Orange Ave | C15: Boy Scout Rd to Lakeview Dr | D15: COUNTY | E15: 553 | F15: (404, 327)* | G15: 8813 | H15: 6768.5 | I15: 6579 | J15: 7452 | K15: 7061 | L15: 6669 | M15: 5495 | N15: 6069 | O15: 5638 | P15: 5319 | Q15: 4774 | R15: 4419 | S15: 3846 | T15: 4987 | U15: 5113 | V15: 5210 | W15: 5120 | X15: 4961 | Y15: 4884 | Z15: 4837 | AA15: 4018 | AB15: 4255 | AC15: 3797 | AD15: 3743 | AE15: 4036 | AF15: 4159 | AG15: 6459 | AH15: 6801 | AI15: 5889 | AJ15: 4966 | AK15: 5963 | AL15: 5812 | AM15: 4018
A16: Min Coll | B16: Binion Rd/Orange Ave | C16: Ocoee-Apopka Rd to Harmon Rd | D16: COUNTY | E16: 28 | F16: 28* | G16: 7282 | H16: 5535 | I16: 5553 | J16: 5391 | K16: 5000 | L16: 4609 | M16: 4249 | N16: 3857 | O16: 4171 | P16: 3844 | Q16: 3580 | R16: 3324 | S16: 3090 | T16: 4141 | U16: 4099 | V16: 440 | W16: 3848 | X16: 3713 | Y16: 4305 | Z16: 4144 | AA16: 4234 | AB16: 4058 | AC16: 3863 | AD16: 4885 | AE16: 4181 | AF16: --- | AG16: --- | AH16: --- | AI16: --- | AJ16: --- | AK16: --- | AL16: --- | AM16: ---
A17: Min Coll | B17: Binion Rd/Orange Ave | C17: Harmon Rd to Boy Scout Rd | D17: CITY | E17: 673 | F17: 673 | G17: 9014 | H17: 7958 | I17: 7352 | J17: 6015 | K17: 5831 | L17: 5647 | M17: 5407 | N17: 5029 | O17: 4585 | P17: 4253 | Q17: 3899 | R17: 3767 | S17: 3090 | T17: 4141 | U17: 4099 | V17: 440 | W17: 3848 | X17: 3713 | Y17: 4305 | Z17: 4144 | AA17: 4234 | AB17: 4058 | AC17: 3863 | AD17: 4885 | AE17: 4181 | AF17: --- | AG17: --- | AH17: --- | AI17: --- | AJ17: --- | AK17: --- | AL17: --- | AM17: ---
A18: Min Coll | B18: Boy Scout Rd | C18: Binion Rd to Ocoee-Apopka Rd | D18: CITY | E18: 556 | F18: 556 | G18: 2992 | H18: 2567 | I18: 2297 | J18: 1790 | K18: 1643 | L18: 1495 | M18: 1401 | N18: 1347 | O18: 1286 | P18: 1115 | Q18: 1062 | R18: 933 | S18: 869 | T18: 986 | U18: 1401 | V18: 1205 | W18: 1023 | X18: 870 | Y18: 1033 | Z18: 1137 | AA18: 687 | AB18: 709 | AC18: 559 | AD18: 483 | AE18: 684 | AF18: 629 | AG18: 567 | AH18: 531 | AI18: 486 | AJ18: --- | AK18: --- | AL18: --- | AM18: ---
A19: Min Coll | B19: Bradshaw Rd | C19: US 441 to Ocoee-Apopka Rd | D19: CITY | E19: 557 | F19: 557 | G19: 8963 | H19: 8276 | I19: 7849 | J19: 7474 | K19: 6579 | L19: 5685 | M19: 7134 | N19: 6823 | O19: 4579 | P19: 4329 | Q19: 3458 | R19: 3351 | S19: 3021 | T19: 3053 | U19: 3980 | V19: 2944 | W19: 3792 | X19: 2626 | Y19: 2667 | Z19: 4612 | AA19: 4271 | AB19: 2727 | AC19: 3521 | AD19: 3868 | AE19: 2451 | AF19: 2479 | AG19: 2403 | AH19: 3994 | AI19: 3178 | AJ19: 3096 | AK19: 3251 | AL19: 3164 | AM19: 372
A20: Min Art | B20: CR 424 (Alabama Ave/Apopka Blvd) | C20: Hiawassee Rd to Overland Rd | D20: COUNTY | E20: 33.1 | F20: 33* | G20: 7749 | H20: 7398 | I20: 7268 | J20: 7194 | K20: 6825 | L20: 6455 | M20: 7923 | N20: 7943 | O20: 7443 | P20: 7515 | Q20: 7218 | R20: 6811 | S20: 6722 | T20: 6510 | U20: 6093 | V20: 6249 | W20: 6387 | X20: 7866 | Y20: 7653 | Z20: 8506 | AA20: 8056 | AB20: 17041 | AC20: 12175 | AD20: N/A | AE20: 8012 | AF20: 8671 | AG20: 7549 | AH20: --- | AI20: --- | AJ20: --- | AK20: --- | AL20: --- | AM20: ---
A21: Min Art | B21: CR 424 (Alabama Ave/Apopka Blvd) | C21: 8th St to Sheeler Rd | D21: COUNTY | E21: 651 | F21: 1008* | G21: 4985 | H21: 4898 | I21: 4924 | J21: 4781 | K21: 4520 | L21: 4259 | M21: 4725 | N21: 4710 | O21: 4566 | P21: 4629 | Q21: 4013 | R21: 3910 | S21: 4217 | T21: 4170 | U21: 3920 | V21: 4137 | W21: 4610 | X21: 5429 | Y21: 5715 | Z21: 6310 | AA21: 5730 | AB21: 5892 | AC21: 6053 | AD21: 4287 | AE21: 7141 | AF21: 5417 | AG21: 5920 | AH21: 5707 | AI21: 5411 | AJ21: 5432 | AK21: 5114 | AL21: 4776 | AM21: 3669
A22: Min Art | B22: CR 424 (Alabama Ave/Apopka Blvd) | C22: Overland Rd to US 441 | D22: CITY | E22: 671 | F22: 671 | G22: 6157 | H22: 5953 | I22: 5856 | J22: 5888 | K22: 5437 | L22: 4986 | M22: 6034 | N22: 5792 | O22: 5196 | P22: 5541 | Q22: 4748 | R22: 5230 | S22: --- | T22: --- | U22: --- | V22: --- | W22: --- | X22: --- | Y22: --- | Z22: --- | AA22: --- | AB22: --- | AC22: --- | AD22: --- | AE22: --- | AF22: --- | AG22: --- | AH22: --- | AI22: --- | AJ22: --- | AK22: --- | AL22: --- | AM22: ---
A23: Min Art | B23: CR 424 (Alabama Ave/Apopka Blvd) | C23: Lakeville Rd to Hiawassee Rd | D23: CITY | E23: 658 | F23: 658 | G23: 12357 | H23: 12178 | I23: 12042 | J23: 12259 | K23: 11530 | L23: 10801 | M23: 12180 | N23: 11748 | O23: 11735 | P23: 11564 | Q23: 11091 | R23: 9693 | S23: 11284 | T23: 10347 | U23: 9948 | V23: 10173 | W23: 10953 | X23: 12331 | Y23: 12100 | Z23: 12215 | AA23: 13590 | AB23: 12657 | AC23: 12128 | AD23: 10157 | AE23: 15451 | AF23: 15457 | AG23: 13560 | AH23: 12223 | AI23: 9834 | AJ23: 8469 | AK23: 7335 | AL23: --- | AM23: ---
A24: Min Art | B24: CR 424 (Alabama Ave/Apopka Blvd) | C24: Sheeler Rd to Lakeville Rd | D24: COUNTY | E24: 653 | F24: 7033* | G24: 9464 | H24: 8819 | I24: 9359 | J24: 8955 | K24: 8672 | L24: 8389 | M24: 9386 | N24: 9166 | O24: 9050 | P24: 8873 | Q24: 8325 | R24: 7577 | S24: 8092 | T24: 7583 | U24: 7090 | V24: 7557 | W24: 8157 | X24: 9391 | Y24: 10407 | Z24: 10829 | AA24: 10471 | AB24: 9510 | AC24: 10010 | AD24: 10898 | AE24: 11667 | AF24: 10452 | AG24: 10337 | AH24: 10308 | AI24: 7992 | AJ24: 8425 | AK24: 5215 | AL24: 7374 | AM24: 4032
A25: Min Art | B25: CR 424 (Alabama Ave/Apopka Blvd) | C25: US 441 to 8th St | D25: CITY | E25: 670 | F25: 670 | G25: 2343 | H25: 2366 | I25: 2462 | J25: 2496 | K25: 2576 | L25: 2657 | M25: 3010 | N25: 2700 | O25: 3419 | P25: 4651 | Q25: 2353 | R25: 2478 | S25: 3251 | T25: 3844 | U25: 3814 | V25: 2081 | W25: 4250 | X25: 4900 | Y25: 11111 | Z25: 5757 | AA25: 2474 | AB25: 2146 | AC25: 2580 | AD25: 2293 | AE25: N.C. | AF25: 2457 | AG25: 2678 | AH25: 2789 | AI25: 2779 | AJ25: 2763 | AK25: 3986 | AL25: 2436 | AM25: 3491
A26: Min Art | B26: CR 435 (Rock Spring Rd/Park Ave/Clarcona Rd) | C26: Keene Rd to McCormick Rd | D26: COUNTY | E26: 565 | F26: (32, 7004)* | G26: 17509 | H26: 17128 | I26: 16247 | J26: 15366 | K26: 14423 | L26: 13481 | M26: 14974 | N26: 14508 | O26: 14831 | P26: 13945 | Q26: 13302 | R26: 12897 | S26: 12077 | T26: 11850 | U26: 11419 | V26: 10559 | W26: 10768 | X26: 10444 | Y26: 11326 | Z26: 12022 | AA26: 11334 | AB26: 7760 | AC26: 12454 | AD26: 11890 | AE26: 12197 | AF26: 12338 | AG26: 13762 | AH26: 13193 | AI26: 11754 | AJ26: --- | AK26: --- | AL26: --- | AM26: ---
A27: Min Art | B27: CR 435 (Rock Spring Rd/Park Ave/Clarcona Rd) | C27: M. Gladden Blvd to Cleveland St | D27: COUNTY | E27: 328.1 | F27: 328* | G27: 10985 | H27: 11280 | I27: 11410 | J27: 11186 | K27: 10988 | L27: 10791 | M27: 11507 | N27: 11360 | O27: 12219 | P27: 10674 | Q27: 10442 | R27: 9551 | S27: 8776 | T27: 9028 | U27: 8444 | V27: 8350 | W27: 9754 | X27: 8582 | Y27: 10264 | Z27: 10704 | AA27: 9801 | AB27: 9657 | AC27: 12799 | AD27: 10329 | AE27: 10204 | AF27: 8329 | AG27: 10040 | AH27: 11151 | AI27: 11323 | AJ27: 9534 | AK27: 11829 | AL27: 10355 | AM27: 8416
A28: Min Art | B28: CR 435 (Rock Spring Rd/Park Ave/Clarcona Rd) | C28: Votaw Rd to Orange St | D28: COUNTY | E28: 426 | F28: 426* | G28: 22457 | H28: 21149 | I28: 22946 | J28: 22719 | K28: 22690 | L28: 22661 | M28: 22830 | N28: 22536 | O28: 23636 | P28: 23842 | Q28: 21855 | R28: 22406 | S28: 21130 | T28: 18979 | U28: 22458 | V28: 23278 | W28: 22742 | X28: 22388 | Y28: 24347 | Z28: 24888 | AA28: 25616 | AB28: 24421 | AC28: 24778 | AD28: 21384 | AE28: 23062 | AF28: 19600 | AG28: 20080 | AH28: 19972 | AI28: 20417 | AJ28: 20313 | AK28: 20660 | AL28: 15482 | AM28: 14500
A29: Min Art | B29: CR 435 (Rock Spring Rd/Park Ave/Clarcona Rd) | C29: Welch Rd to Sandpiper Rd | D29: COUNTY | E29: 21 | F29: 21* | G29: 25667 | H29: 26426 | I29: 24859 | J29: 24135 | K29: 23950 | L29: 23766 | M29: 24272 | N29: 23827 | O29: 24393 | P29: 21222 | Q29: 22029 | R29: 21530 | S29: 21075 | T29: 22035 | U29: 23240 | V29: 23361 | W29: 21435 | X29: 22211 | Y29: 22299 | Z29: 23771 | AA29: 21724 | AB29: 21844 | AC29: 19290 | AD29: 16176 | AE29: 16999 | AF29: 16499 | AG29: 16816 | AH29: 16079 | AI29: 14598 | AJ29: 14416 | AK29: 12839 | AL29: 11565 | AM29: 15131
A30: Min Art | B30: CR 435 (Rock Spring Rd/Park Ave/Clarcona Rd) | C30: Ponkan Rd to Welch Rd | D30: COUNTY | E30: 19 | F30: 19* | G30: 24048 | H30: 24053 | I30: 23417 | J30: 23080 | K30: 25429 | L30: 27779 | M30: 24304 | N30: 20180 | O30: 24207 | P30: 22072 | Q30: 19585 | R30: 20930 | S30: 18786 | T30: 19287 | U30: 22625 | V30: 22064 | W30: 18894 | X30: 21817 | Y30: 22682 | Z30: 24614 | AA30: 20868 | AB30: 20611 | AC30: 23624 | AD30: CST. | AE30: 17417 | AF30: 18701 | AG30: 16681 | AH30: 15961 | AI30: 15090 | AJ30: 12208 | AK30: 13236 | AL30: 13965 | AM30: 13385
A31: Min Art | B31: CR 435 (Rock Spring Rd/Park Ave/Clarcona Rd) | C31: McCormick Rd to Clarcona-Ocoee Rd | D31: CITY | E31: 7004 | F31: 7004 | G31: 15230 | H31: 21455 | I31: 21234 | J31: 33275 | K31: 24330 | L31: 15386 | M31: 16178 | N31: 15659 | O31: 16393 | P31: 15286 | Q31: 14159 | R31: 13962 | S31: 11792 | T31: 13290 | U31: 11119 | V31: 11804 | W31: 11905 | X31: 12188 | Y31: 13239 | Z31: 11719 | AA31: 12490 | AB31: 11525 | AC31: 15841 | AD31: N/A | AE31: 12045 | AF31: 12616 | AG31: 13756 | AH31: 14847 | AI31: 12700 | AJ31: --- | AK31: --- | AL31: --- | AM31: ---
A32: Min Art | B32: CR 435 (Rock Spring Rd/Park Ave/Clarcona Rd) | C32: Sandpiper Rd to Votaw Rd | D32: CITY | E32: 516 | F32: 516 | G32: 22569 | H32: 23228 | I32: 23164 | J32: 25324 | K32: 23009 | L32: 20693 | M32: 23717 | N32: 22652 | O32: 22978 | P32: 21998 | Q32: 21560 | R32: 20280 | S32: 19095 | T32: 19958 | U32: 19995 | V32: 20702 | W32: 20907 | X32: 21121 | Y32: 21808 | Z32: 22662 | AA32: 23837 | AB32: 21898 | AC32: 22251 | AD32: 20412 | AE32: 18017 | AF32: 19253 | AG32: 19645 | AH32: 17648 | AI32: 17109 | AJ32: --- | AK32: --- | AL32: --- | AM32: ---
A33: Min Art | B33: CR 435 (Rock Spring Rd/Park Ave/Clarcona Rd) | C33: US 441 to M. Gladden Blvd | D33: CITY | E33: 563 | F33: 563 | G33: 11434 | H33: 12123 | I33: 12626 | J33: 13503 | K33: 13725 | L33: 13948 | M33: 14548 | N33: 13181 | O33: 15026 | P33: 15274 | Q33: 13011 | R33: 12567 | S33: 12258 | T33: 11017 | U33: 12347 | V33: 11113 | W33: 11698 | X33: 12203 | Y33: 12951 | Z33: 12305 | AA33: 12212 | AB33: 13252 | AC33: 13283 | AD33: 12023 | AE33: 12552 | AF33: 11798 | AG33: 13555 | AH33: 13721 | AI33: 12991 | AJ33: 10743 | AK33: 15538 | AL33: 13202 | AM33: 13082
A34: Min Art | B34: CR 435 (Rock Spring Rd/Park Ave/Clarcona Rd) | C34: Orange St to US 441 | D34: CITY | E34: 580 | F34: 580 | G34: 25032 | H34: 22581 | I34: 22288 | J34: 18213 | K34: 20357 | L34: 22501 | M34: 23003 | N34: 25626 | O34: 24652 | P34: 25252 | Q34: 24740 | R34: 23326 | S34: 22652 | T34: 22280 | U34: 23429 | V34: 24442 | W34: 23869 | X34: 24129 | Y34: 27217 | Z34: 26484 | AA34: 27259 | AB34: 26362 | AC34: 27035 | AD34: 24142 | AE34: N.C. | AF34: 24635 | AG34: 23000 | AH34: 22902 | AI34: 24996 | AJ34: 20776 | AK34: 18844 | AL34: 16345 | AM34: 16746
