Workbook
Name E: #N/A
Name f: #N/A
Name IC: #REF!
Name ICB: #REF!
Name Intersection: [1]TGen!#REF!
Name k: [1]TGen!#REF!
Name new: [1]TGen!#REF!
Name PB: #REF!
Name Private_School__K_8: [1]TGen!#REF!

Sheet 2025 RNCR
A2: Count Station # | B2: Count Source | C2: ROADWAY | D2: FROM | E2: TO | F2: Area Type (U/T/R) | G2: Functional Class | I2: Adjusted Service Volumes (Peak Hour Peak Direction) | M2: Latest Count Year | N2: Count Date (mm/dd) | O2: Week | P2: ADT | Q2: AADT | R2: PM Peak Hour
H3: Context Class | I3: B | J3: C | K3: D | L3: E | R3: NB/EB | S3: SB/WB | T3: Pk Hr Total | U3: Pk Dir | V3: K-Factor | W3: D-Factor | X3: Pk Hr Pk Dir Vol | Y3: LOS | Z3: Capacity | AA3: V/C
A5: 544 | B5: OC | C5: Bass Highway | D5: Pine Grove Rd | E5: End | F5: U | G5: Collector | H5: C3R | I5: 0 | J5: 730 | K5: 830 | L5: 830 | M5: 2012 | N5: 3/27 | O5: 13 | P5: 2441 | Q5: 2368 | R5: 123 | S5: 92 | T5: 215 | U5: NB/EB | V5: 0.0881 | W5: 0.57 | X5: 123 | Y5: C | Z5: 830 | AA5: 0.15
A6: 9009 | B6: OC | C6: Absher Rd | D6: Southern Terminus | E6: Cyrils Dr | F6: RD | G6: Local | H6: C3R | I6: 0 | J6: 680 | K6: 780 | L6: 780 | M6: 2025 | N6: 4/16 | O6: 16 | P6: 219 | Q6: 212 | R6: 13 | S6: 8 | T6: 21 | U6: NB/EB | V6: 0.096 | W6: 0.62 | X6: 13 | Y6: C | Z6: 680 | AA6: 0.02
A7: 9016 | B7: OC | C7: Ball Park Rd | D7: John Young Pkwy | E7: Thacker Ave | F7: U | G7: Collector | H7: C3C | I7: 0 | J7: 1370 | K7: 1630 | L7: 1630 | M7: 2025 | N7: 3/25 | O7: 13 | P7: 14654 | Q7: 14214 | R7: 445 | S7: 581 | T7: 1026 | U7: SB/WB | V7: 0.07 | W7: 0.57 | X7: 581 | Y7: C | Z7: 1630 | AA7: 0.36
A8: 177 | B8: OC | C8: Bass Road | D8: Yowell Rd | E8: US 192 | F8: U | G8: Collector | H8: C3C | I8: 0 | J8: 720 | K8: 1020 | L8: 1020 | M8: 2025 | N8: 2/26 | O8: 9 | P8: 9541 | Q8: 9350 | R8: 307 | S8: 336 | T8: 643 | U8: SB/WB | V8: 0.067 | W8: 0.52 | X8: 336 | Y8: C | Z8: 1020 | AA8: 0.33
A9: 183.1 | B9: OC | C9: Bella Citta Blvd | D9: Oasis Club Blvd | E9: Westside Blvd | F9: U | G9: Collector | H9: C3R | I9: 0 | J9: 920 | K9: 1050 | L9: 1050 | M9: 2025 | N9: 3/4 | O9: 10 | P9: 12857 | Q9: 12471 | R9: 479 | S9: 487 | T9: 966 | U9: SB/WB | V9: 0.075 | W9: 0.5 | X9: 487 | Y9: C | Z9: 1050 | AA9: 0.46
A10: 184 | B10: OC | C10: Bella Citta Blvd | D10: Westside Blvd | E10: S Goodman Rd | F10: U | G10: Collector | H10: C3R | I10: 0 | J10: 920 | K10: 1050 | L10: 1050 | M10: 2025 | N10: 3/4 | O10: 10 | P10: 11288 | Q10: 10949 | R10: 408 | S10: 424 | T10: 832 | U10: SB/WB | V10: 0.074 | W10: 0.51 | X10: 424 | Y10: C | Z10: 1050 | AA10: 0.4
A11: 467 | B11: OC | C11: Bill Beck Blvd | D11: US 192-441 | E11: Fortune Rd | F11: U | G11: Collector | H11: C3C | I11: 0 | J11: 1440 | K11: 1720 | L11: 1720 | M11: 2025 | N11: 3/26 | O11: 13 | P11: 6719 | Q11: 6517 | R11: 450 | S11: 256 | T11: 706 | U11: NB/EB | V11: 0.105 | W11: 0.64 | X11: 450 | Y11: C | Z11: 1720 | AA11: 0.26
A12: 9015 | B12: OC | C12: Bill Beck Blvd | D12: Osceola Pkwy | E12: Woodcrest Blvd | F12: U | G12: Collector | H12: C3R | I12: 0 | J12: 920 | K12: 1050 | L12: 1050 | M12: 2025 | N12: 3/26 | O12: 13 | P12: 6004 | Q12: 5824 | R12: 247 | S12: 277 | T12: 524 | U12: SB/WB | V12: 0.087 | W12: 0.53 | X12: 277 | Y12: C | Z12: 1050 | AA12: 0.26
A13: 474 | B13: OC | C13: Boggy Creek Rd (East) | D13: Simpson Rd | E13: Austin Tyndell Park | F13: U | G13: Minor Art | H13: C3R | I13: 0 | J13: 920 | K13: 1050 | L13: 1050 | M13: Under Construction
A14: 475 | B14: OC | C14: Boggy Creek Rd (East) | D14: Austin Tyndell Park | E14: Narcoossee Rd (CR 15) | F14: U | G14: Minor Art | H14: C3R | I14: 0 | J14: 920 | K14: 1050 | L14: 1050 | M14: Under Construction
A15: 9019 | B15: OC | C15: Botanica Blvd | D15: US 192-441 | E15: Crispin Cir | F15: U | G15: Collector | H15: C3R | I15: 0 | J15: 1530 | K15: 1670 | L15: 1670 | M15: 2025 | N15: 4/1 | O15: 14 | P15: 4684 | Q15: 4543 | R15: 248 | S15: 121 | T15: 369 | U15: NB/EB | V15: 0.079 | W15: 0.67 | X15: 248 | Y15: C | Z15: 1670 | AA15: 0.15
A16: 2024 | B16: OC | C16: Broad St | D16: US 17/92 | E16: Old Tampa Hwy | F16: U | G16: Collector | H16: C3C | I16: 0 | J16: 530 | K16: 750 | L16: 750 | M16: 2025 | N16: 4/9 | O16: 15 | P16: 6530 | Q16: 6334 | R16: 249 | S16: 286 | T16: 535 | U16: SB/WB | V16: 0.082 | W16: 0.53 | X16: 286 | Y16: C | Z16: 750 | AA16: 0.38
A17: 510 | B17: OC | C17: Brown Chapel Rd | D17: US 192-441 | E17: Lakeshore Blvd | F17: U | G17: Collector | H17: C3R | I17: 0 | J17: 970 | K17: 1110 | L17: 1110 | M17: 2025 | N17: 3/12 | O17: 11 | P17: 9205 | Q17: 8929 | R17: 352 | S17: 349 | T17: 701 | U17: NB/EB | V17: 0.076 | W17: 0.5 | X17: 352 | Y17: C | Z17: 1110 | AA17: 0.32
A18: 462 | B18: OC | C18: Buenaventura Blvd | D18: Simpson Rd | E18: Florida Pkwy | F18: U | G18: Minor Art | H18: C3R | I18: 0 | J18: 1620 | K18: 1760 | L18: 1760 | M18: 2025 | N18: 4/8 | O18: 15 | P18: 27382 | Q18: 26561 | R18: 1296 | S18: 924 | T18: 2220 | U18: NB/EB | V18: 0.081 | W18: 0.58 | X18: 1296 | Y18: C | Z18: 1760 | AA18: 0.74
A19: 456 | B19: OC | C19: Buenaventura Blvd | D19: Florida Pkwy | E19: Osceola Pkwy | F19: U | G19: Minor Art | H19: C3R | I19: 0 | J19: 1620 | K19: 1760 | L19: 1760 | M19: 2025 | N19: 3/26 | O19: 13 | P19: 32097 | Q19: 31134 | R19: 941 | S19: 1560 | T19: 2501 | U19: SB/WB | V19: 0.078 | W19: 0.62 | X19: 1560 | Y19: C | Z19: 1760 | AA19: 0.89
A20: 452 | B20: OC | C20: Buenaventura Blvd | D20: Osceola Pkwy | E20: Orange County Line | F20: U | G20: Minor Art | H20: C3R | I20: 0 | J20: 1620 | K20: 1760 | L20: 1760 | M20: 2025 | N20: 4/8 | O20: 15 | P20: 38082 | Q20: 36940 | R20: 1136 | S20: 2226 | T20: 3362 | U20: SB/WB | V20: 0.088 | W20: 0.66 | X20: 2226 | Y20: F | Z20: 1760 | AA20: 1.26
A21: 605 | B21: OC | C21: Canoe Creek Rd (CR 523) | D21: US 441/SR 15/Holopaw Rd | E21: Sullivan Dr | F21: RU | G21: Major Coll | H21: C2 | I21: 240 | J21: 430 | K21: 730 | L21: 1490 | M21: 2025 | N21: 4/9 | O21: 15 | P21: 2556 | Q21: 2479 | R21: 99 | S21: 100 | T21: 199 | U21: SB/WB | V21: 0.078 | W21: 0.5 | X21: 100 | Y21: B | Z21: 430 | AA21: 0.23
A22: 523 | B22: OC | C22: Canoe Creek Rd (CR 523) | D22: Sullivan Dr | E22: Deer Run Rd | F22: T | G22: Minor Art | H22: C3R | I22: 0 | J22: 870 | K22: 1000 | L22: 1000 | M22: 2025 | N22: 4/8 | O22: 15 | P22: 6450 | Q22: 6257 | R22: 306 | S22: 231 | T22: 537 | U22: NB/EB | V22: 0.083 | W22: 0.57 | X22: 306 | Y22: C | Z22: 870 | AA22: 0.35
A23: 522 | B23: OC | C23: Canoe Creek Rd (CR 523) | D23: Deer Run Rd | E23: Old Canoe Creek Rd | F23: U | G23: Minor Art | H23: C3R | I23: 0 | J23: 970 | K23: 1110 | L23: 1110 | M23: 2025 | N23: 4/8 | O23: 15 | P23: 22804 | Q23: 22120 | R23: 1040 | S23: 719 | T23: 1759 | U23: NB/EB | V23: 0.077 | W23: 0.59 | X23: 1040 | Y23: D | Z23: 1110 | AA23: 0.94
A24: 508 | B24: OC | C24: Canoe Creek Rd (CR 523) | D24: Old Canoe Creek Rd | E24: Nolte Rd | F24: U | G24: Minor Art | H24: C3R | I24: 0 | J24: 970 | K24: 1110 | L24: 1110 | M24: 2025 | N24: 4/1 | O24: 14 | P24: 17650 | Q24: 17121 | R24: 720 | S24: 698 | T24: 1418 | U24: NB/EB | V24: 0.08 | W24: 0.51 | X24: 720 | Y24: C | Z24: 1110 | AA24: 0.65
A25: 521 | B25: OC | C25: Canoe Creek Rd (CR 523) | D25: Nolte Rd | E25: US 192-441 | F25: U | G25: Minor Art | H25: C3R | I25: 0 | J25: 970 | K25: 1110 | L25: 1110 | M25: 2025 | N25: 4/1 | O25: 14 | P25: 16789 | Q25: 16285 | R25: 592 | S25: 720 | T25: 1312 | U25: SB/WB | V25: 0.078 | W25: 0.55 | X25: 720 | Y25: C | Z25: 1110 | AA25: 0.65
A26: 9012 | B26: OC | C26: Canoe Creek Rd (CR 523) | D26: Mildred Bass Rd | E26: Florida's Turnpike | F26: U | G26: Minor Art | H26: C2 | I26: 240 | J26: 430 | K26: 730 | L26: 1490 | M26: Under Construction
A27: 311 | B27: OC | C27: Carroll St | D27: Columbia Ave | E27: Dyer Blvd | F27: U | G27: Minor Art | H27: C3R | I27: 0 | J27: 1620 | K27: 1760 | L27: 1760 | M27: 2025 | N27: 2/25 | O27: 9 | P27: 20483 | Q27: 20073 | R27: 689 | S27: 599 | T27: 1288 | U27: NB/EB | V27: 0.063 | W27: 0.53 | X27: 689 | Y27: C | Z27: 1760 | AA27: 0.39
A28: 312 | B28: OC | C28: Carroll St | D28: Dyer Blvd | E28: Thacker Ave | F28: U | G28: Minor Art | H28: C3R | I28: 0 | J28: 1620 | K28: 1760 | L28: 1760 | M28: 2025 | N28: 3/25 | O28: 13 | P28: 11845 | Q28: 11490 | R28: 543 | S28: 434 | T28: 977 | U28: NB/EB | V28: 0.082 | W28: 0.56 | X28: 543 | Y28: C | Z28: 1760 | AA28: 0.31
A29: 309 | B29: OC | C29: Carroll St | D29: Thacker Ave | E29: John Young Pkwy | F29: U | G29: Minor Art | H29: C3R | I29: 0 | J29: 1620 | K29: 1760 | L29: 1760 | M29: 2025 | N29: 3/25 | O29: 13 | P29: 17325 | Q29: 16805 | R29: 684 | S29: 795 | T29: 1479 | U29: SB/WB | V29: 0.085 | W29: 0.54 | X29: 795 | Y29: C | Z29: 1760 | AA29: 0.45
A30: 313 | B30: OC | C30: Carroll St | D30: John Young Pkwy | E30: Main St/US 441-17/92 | F30: U | G30: Minor Art | H30: C4 | I30: 0 | J30: 0 | K30: 870 | L30: 1190 | M30: 2025 | N30: 3/25 | O30: 13 | P30: 19371 | Q30: 18790 | R30: 533 | S30: 536 | T30: 1069 | U30: SB/WB | V30: 0.055 | W30: 0.5 | X30: 536 | Y30: D | Z30: 870 | AA30: 0.62
A31: 314 | B31: OC | C31: Carroll St | D31: Main St/US 441-17/92 | E31: Old Dixie Hwy | F31: U | G31: Minor Art | H31: C4 | I31: 0 | J31: 0 | K31: 870 | L31: 1190 | M31: 2025 | N31: 3/26 | O31: 13 | P31: 12815 | Q31: 12431 | R31: 554 | S31: 451 | T31: 1005 | U31: NB/EB | V31: 0.078 | W31: 0.55 | X31: 554 | Y31: D | Z31: 870 | AA31: 0.64
A32: 315 | B32: OC | C32: Carroll St | D32: Old Dixie Hwy | E32: Michigan Ave | F32: U | G32: Minor Art | H32: C4 | I32: 0 | J32: 1090 | K32: 1610 | L32: 1820 | M32: 2025 | N32: 3/26 | O32: 13 | P32: 13450 | Q32: 13047 | R32: 665 | S32: 439 | T32: 1104 | U32: NB/EB | V32: 0.082 | W32: 0.6 | X32: 665 | Y32: C | Z32: 1610 | AA32: 0.41
A33: 153 | B33: OC | C33: Celebration Ave | D33: US 192 | E33: Celebration Blvd | F33: U | G33: Collector | H33: C3C | I33: 0 | J33: 1440 | K33: 1720 | L33: 1720 | M33: 2025 | N33: 3/5 | O33: 10 | P33: 16235 | Q33: 15748 | R33: 819 | S33: 546 | T33: 1365 | U33: NB/EB | V33: 0.084 | W33: 0.6 | X33: 819 | Y33: C | Z33: 1720 | AA33: 0.48
A34: 154 | B34: OC | C34: Celebration Blvd | D34: Celebration Pl | E34: World Dr | F34: U | G34: Collector | H34: C3C | I34: 0 | J34: 1440 | K34: 1720 | L34: 1720 | M34: 2025 | N34: 4/9 | O34: 15 | P34: 18436 | Q34: 17883 | R34: 667 | S34: 923 | T34: 1590 | U34: SB/WB | V34: 0.086 | W34: 0.58 | X34: 923 | Y34: C | Z34: 1720 | AA34: 0.54
A35: 122 | B35: OC | C35: Champions Gate Blvd | D35: Polk County Line | E35: I-4 | F35: U | G35: Collector | H35: C3C | I35: 0 | J35: 1440 | K35: 1720 | L35: 1720 | M35: 2025 | N35: 3/4 | O35: 10 | P35: 35950 | Q35: 34872 | R35: 1100 | S35: 1331 | T35: 2431 | U35: SB/WB | V35: 0.068 | W35: 0.55 | X35: 1331 | Y35: C | Z35: 1720 | AA35: 0.77
A36: 304 | B36: OC | C36: Clay St | D36: Jack Calhoun Dr | E36: Thacker Ave | F36: U | G36: Collector | H36: C3R | I36: 0 | J36: 870 | K36: 1000 | L36: 1000 | M36: 2025 | N36: 2/26 | O36: 9 | P36: 18195 | Q36: 17831 | R36: 481 | S36: 1010 | T36: 1491 | U36: SB/WB | V36: 0.082 | W36: 0.68 | X36: 1010 | Y36: F | Z36: 1000 | AA36: 1.01
A37: 303 | B37: OC | C37: Clay St | D37: Thacker Ave | E37: Randolph Ave | F37: U | G37: Collector | H37: C3R | I37: 0 | J37: 730 | K37: 830 | L37: 830 | M37: 2025 | N37: 2/26 | O37: 9 | P37: 8529 | Q37: 8358 | R37: 213 | S37: 618 | T37: 831 | U37: SB/WB | V37: 0.097 | W37: 0.74 | X37: 618 | Y37: C | Z37: 830 | AA37: 0.74
A38: 537 | B38: OC | C38: Creek Woods Dr | D38: Canoe Creek Rd | E38: Michigan Ave | F38: U | G38: Collector | H38: C3R | I38: 0 | J38: 920 | K38: 1050 | L38: 1050 | M38: 2025 | N38: 4/1 | O38: 14 | P38: 3599 | Q38: 3491 | R38: 191 | S38: 121 | T38: 312 | U38: NB/EB | V38: 0.087 | W38: 0.61 | X38: 191 | Y38: C | Z38: 1050 | AA38: 0.18
... A44: 9000 | B44: OC | C44: Cypress Pkwy | D44: Poinciana Pkwy | E44: Marigold Ave | F44: U | G44: Local | H44: C3C | I44: 0 | J44: 720 | K44: 1020 | L44: 1020 | M44: 2025 | N44: 2/27 | O44: 9 | P44: 17078 | Q44: 16736 | R44: 729 | S44: 524 | T44: 1253 | U44: NB/EB | V44: 0.073 | W44: 0.58 | X44: 729 | Y44: D | Z44: 1020 | AA44: 0.71
A45: 1001 | B45: OC | C45: Cyrils Dr | D45: Narcoossee Rd | E45: Zuni Rd | F45: U | G45: Collector | H45: C3R | I45: 0 | J45: 730 | K45: 830 | L45: 830 | M45: Under Construction
A46: 1002 | B46: OC | C46: Cyrils Dr | D46: Zuni Rd | E46: Absher Rd | F46: U | G46: Collector | H46: C3R | I46: 0 | J46: 870 | K46: 1000 | L46: 1000 | M46: Under Construction
A47: 552 | B47: OC | C47: Cyrils Dr | D47: Narcoossee Rd (CR 15) | E47: Absher Rd | F47: T | G47: Local | H47: C3R | I47: 0 | J47: 920 | K47: 1050 | L47: 1050 | M47: 2009 | N47: 4/14 | O47: 16 | P47: 1112 | Q47: 1079 | R47: 68 | S47: 34 | T47: 102 | U47: NB/EB | V47: 0.092 | W47: 0.67 | X47: 68 | Y47: C | Z47: 920 | AA47: 0.07
...

Sheet Input
L6: Exiting | O6: Improved | R6: =$AA$2&" Existing Conditions" -> Existing Conditions | AJ6: Daily/2way/Directional per Agency
B7: Seg | C7: Segment Information | F7: Exist | G7: Imp | H7: LOS | I7: Facility | J7: Functional | K7: Context | L7: Daily | M7: 2-Way | N7: Dir | O7: Daily | P7: Peak | Q7: Dir | R7: Daily | U7: AM 2-Way | X7: PM 2-Way | AA7: AM Directional | AE7: PM Directional | AI7: GR | AJ7: Adjusted Service Volumes
B8: ID | C8: Roadway | D8: From | E8: To | F8: Lns | G8: Lns | H8: Std | I8: Type | J8: Class | K8: Classification | L8: Cap | M8: Cap | N8: Cap | O8: Cap | P8: Cap | Q8: Cap | R8: Volume | S8: V/C | T8: LOS | U8: Vol | V8: V/C | W8: LOS | X8: Vol | Y8: V/C | Z8: LOS | AA8: NB/EB | AB8: SB/WB | AC8: V/C | AD8: LOS | AE8: NB/EB | AF8: SB/WB | AG8: V/C | AH8: LOS | AJ8: B | AK8: C | AL8: D | AM8: E
B9: ='2025 RNCR'!A5 -> 544 | C9: ='2025 RNCR'!C5 -> Bass Highway | D9: ='2025 RNCR'!D5 -> Pine Grove Rd | E9: ='2025 RNCR'!E5 -> End | H9: =IF('2025 RNCR'!F5="U","D",IF('2025 RNCR'!F5="RU","C",IF('2025 RNCR'!F5="T","C","-"))) -> D | J9: ='2025 RNCR'!G5 -> Collector | K9: ='2025 RNCR'!H5 -> C3R | N9: ='2025 RNCR'!Z5 -> 830 | R9: ='2025 RNCR'!Q5 -> 2368 | AE9: ='2025 RNCR'!R5 -> 123 | AF9: ='2025 RNCR'!S5 -> 92 | AG9: ='2025 RNCR'!AA5 -> 0.15 | AH9: ='2025 RNCR'!Y5 -> C | AJ9: ='2025 RNCR'!I5 -> 0 | AK9: ='2025 RNCR'!J5 -> 730 | AL9: ='2025 RNCR'!K5 -> 830 | AM9: ='2025 RNCR'!L5 -> 830
B10: ='2025 RNCR'!A6 -> 9009 | C10: ='2025 RNCR'!C6 -> Absher Rd | D10: ='2025 RNCR'!D6 -> Southern Terminus | E10: ='2025 RNCR'!E6 -> Cyrils Dr | H10: =IF('2025 RNCR'!F6="U","D",IF('2025 RNCR'!F6="RU","C",IF('2025 RNCR'!F6="T","C","-"))) -> - | J10: ='2025 RNCR'!G6 -> Local | K10: ='2025 RNCR'!H6 -> C3R | N10: ='2025 RNCR'!Z6 -> 680 | R10: ='2025 RNCR'!Q6 -> 212 | AE10: ='2025 RNCR'!R6 -> 13 | AF10: ='2025 RNCR'!S6 -> 8 | AG10: ='2025 RNCR'!AA6 -> 0.02 | AH10: ='2025 RNCR'!Y6 -> C | AJ10: ='2025 RNCR'!I6 -> 0 | AK10: ='2025 RNCR'!J6 -> 680 | AL10: ='2025 RNCR'!K6 -> 780 | AM10: ='2025 RNCR'!L6 -> 780
B11: ='2025 RNCR'!A7 -> 9016 | C11: ='2025 RNCR'!C7 -> Ball Park Rd | D11: ='2025 RNCR'!D7 -> John Young Pkwy | E11: ='2025 RNCR'!E7 -> Thacker Ave | H11: =IF('2025 RNCR'!F7="U","D",IF('2025 RNCR'!F7="RU","C",IF('2025 RNCR'!F7="T","C","-"))) -> D | J11: ='2025 RNCR'!G7 -> Collector | K11: ='2025 RNCR'!H7 -> C3C | N11: ='2025 RNCR'!Z7 -> 1630 | R11: ='2025 RNCR'!Q7 -> 14214 | AE11: ='2025 RNCR'!R7 -> 445 | AF11: ='2025 RNCR'!S7 -> 581 | AG11: ='2025 RNCR'!AA7 -> 0.36 | AH11: ='2025 RNCR'!Y7 -> C | AJ11: ='2025 RNCR'!I7 -> 0 | AK11: ='2025 RNCR'!J7 -> 1370 | AL11: ='2025 RNCR'!K7 -> 1630 | AM11: ='2025 RNCR'!L7 -> 1630
B12: ='2025 RNCR'!A8 -> 177 | C12: ='2025 RNCR'!C8 -> Bass Road | D12: ='2025 RNCR'!D8 -> Yowell Rd | E12: ='2025 RNCR'!E8 -> US 192 | H12: =IF('2025 RNCR'!F8="U","D",IF('2025 RNCR'!F8="RU","C",IF('2025 RNCR'!F8="T","C","-"))) -> D | J12: ='2025 RNCR'!G8 -> Collector | K12: ='2025 RNCR'!H8 -> C3C | N12: ='2025 RNCR'!Z8 -> 1020 | R12: ='2025 RNCR'!Q8 -> 9350 | AE12: ='2025 RNCR'!R8 -> 307 | AF12: ='2025 RNCR'!S8 -> 336 | AG12: ='2025 RNCR'!AA8 -> 0.33 | AH12: ='2025 RNCR'!Y8 -> C | AJ12: ='2025 RNCR'!I8 -> 0 | AK12: ='2025 RNCR'!J8 -> 720 | AL12: ='2025 RNCR'!K8 -> 1020 | AM12: ='2025 RNCR'!L8 -> 1020
B13: ='2025 RNCR'!A9 -> 183.1 | C13: ='2025 RNCR'!C9 -> Bella Citta Blvd | D13: ='2025 RNCR'!D9 -> Oasis Club Blvd | E13: ='2025 RNCR'!E9 -> Westside Blvd | H13: =IF('2025 RNCR'!F9="U","D",IF('2025 RNCR'!F9="RU","C",IF('2025 RNCR'!F9="T","C","-"))) -> D | J13: ='2025 RNCR'!G9 -> Collector | K13: ='2025 RNCR'!H9 -> C3R | N13: ='2025 RNCR'!Z9 -> 1050 | R13: ='2025 RNCR'!Q9 -> 12471 | AE13: ='2025 RNCR'!R9 -> 479 | AF13: ='2025 RNCR'!S9 -> 487 | AG13: ='2025 RNCR'!AA9 -> 0.46 | AH13: ='2025 RNCR'!Y9 -> C | AJ13: ='2025 RNCR'!I9 -> 0 | AK13: ='2025 RNCR'!J9 -> 920 | AL13: ='2025 RNCR'!K9 -> 1050 | AM13: ='2025 RNCR'!L9 -> 1050
B14: ='2025 RNCR'!A10 -> 184 | C14: ='2025 RNCR'!C10 -> Bella Citta Blvd | D14: ='2025 RNCR'!D10 -> Westside Blvd | E14: ='2025 RNCR'!E10 -> S Goodman Rd | H14: =IF('2025 RNCR'!F10="U","D",IF('2025 RNCR'!F10="RU","C",IF('2025 RNCR'!F10="T","C","-"))) -> D | J14: ='2025 RNCR'!G10 -> Collector | K14: ='2025 RNCR'!H10 -> C3R | N14: ='2025 RNCR'!Z10 -> 1050 | R14: ='2025 RNCR'!Q10 -> 10949 | AE14: ='2025 RNCR'!R10 -> 408 | AF14: ='2025 RNCR'!S10 -> 424 | AG14: ='2025 RNCR'!AA10 -> 0.4 | AH14: ='2025 RNCR'!Y10 -> C | AJ14: ='2025 RNCR'!I10 -> 0 | AK14: ='2025 RNCR'!J10 -> 920 | AL14: ='2025 RNCR'!K10 -> 1050 | AM14: ='2025 RNCR'!L10 -> 1050
B15: ='2025 RNCR'!A11 -> 467 | C15: ='2025 RNCR'!C11 -> Bill Beck Blvd | D15: ='2025 RNCR'!D11 -> US 192-441 | E15: ='2025 RNCR'!E11 -> Fortune Rd | H15: =IF('2025 RNCR'!F11="U","D",IF('2025 RNCR'!F11="RU","C",IF('2025 RNCR'!F11="T","C","-"))) -> D | J15: ='2025 RNCR'!G11 -> Collector | K15: ='2025 RNCR'!H11 -> C3C | N15: ='2025 RNCR'!Z11 -> 1720 | R15: ='2025 RNCR'!Q11 -> 6517 | AE15: ='2025 RNCR'!R11 -> 450 | AF15: ='2025 RNCR'!S11 -> 256 | AG15: ='2025 RNCR'!AA11 -> 0.26 | AH15: ='2025 RNCR'!Y11 -> C | AJ15: ='2025 RNCR'!I11 -> 0 | AK15: ='2025 RNCR'!J11 -> 1440 | AL15: ='2025 RNCR'!K11 -> 1720 | AM15: ='2025 RNCR'!L11 -> 1720
B16: ='2025 RNCR'!A12 -> 9015 | C16: ='2025 RNCR'!C12 -> Bill Beck Blvd | D16: ='2025 RNCR'!D12 -> Osceola Pkwy | E16: ='2025 RNCR'!E12 -> Woodcrest Blvd | H16: =IF('2025 RNCR'!F12="U","D",IF('2025 RNCR'!F12="RU","C",IF('2025 RNCR'!F12="T","C","-"))) -> D | J16: ='2025 RNCR'!G12 -> Collector | K16: ='2025 RNCR'!H12 -> C3R | N16: ='2025 RNCR'!Z12 -> 1050 | R16: ='2025 RNCR'!Q12 -> 5824 | AE16: ='2025 RNCR'!R12 -> 247 | AF16: ='2025 RNCR'!S12 -> 277 | AG16: ='2025 RNCR'!AA12 -> 0.26 | AH16: ='2025 RNCR'!Y12 -> C | AJ16: ='2025 RNCR'!I12 -> 0 | AK16: ='2025 RNCR'!J12 -> 920 | AL16: ='2025 RNCR'!K12 -> 1050 | AM16: ='2025 RNCR'!L12 -> 1050
B17: ='2025 RNCR'!A13 -> 474 | C17: ='2025 RNCR'!C13 -> Boggy Creek Rd (East) | D17: ='2025 RNCR'!D13 -> Simpson Rd | E17: ='2025 RNCR'!E13 -> Austin Tyndell Park | H17: =IF('2025 RNCR'!F13="U","D",IF('2025 RNCR'!F13="RU","C",IF('2025 RNCR'!F13="T","C","-"))) -> D | J17: ='2025 RNCR'!G13 -> Minor Art | K17: ='2025 RNCR'!H13 -> C3R | N17: ='2025 RNCR'!Z13 -> 0 | R17: ='2025 RNCR'!Q13 -> 0 | AE17: ='2025 RNCR'!R13 -> 0 | AF17: ='2025 RNCR'!S13 -> 0 | AG17: ='2025 RNCR'!AA13 -> 0 | AH17: ='2025 RNCR'!Y13 -> 0 | AJ17: ='2025 RNCR'!I13 -> 0 | AK17: ='2025 RNCR'!J13 -> 920 | AL17: ='2025 RNCR'!K13 -> 1050 | AM17: ='2025 RNCR'!L13 -> 1050
B18: ='2025 RNCR'!A14 -> 475 | C18: ='2025 RNCR'!C14 -> Boggy Creek Rd (East) | D18: ='2025 RNCR'!D14 -> Austin Tyndell Park | E18: ='2025 RNCR'!E14 -> Narcoossee Rd (CR 15) | H18: =IF('2025 RNCR'!F14="U","D",IF('2025 RNCR'!F14="RU","C",IF('2025 RNCR'!F14="T","C","-"))) -> D | J18: ='2025 RNCR'!G14 -> Minor Art | K18: ='2025 RNCR'!H14 -> C3R | N18: ='2025 RNCR'!Z14 -> 0 | R18: ='2025 RNCR'!Q14 -> 0 | AE18: ='2025 RNCR'!R14 -> 0 | AF18: ='2025 RNCR'!S14 -> 0 | AG18: ='2025 RNCR'!AA14 -> 0 | AH18: ='2025 RNCR'!Y14 -> 0 | AJ18: ='2025 RNCR'!I14 -> 0 | AK18: ='2025 RNCR'!J14 -> 920 | AL18: ='2025 RNCR'!K14 -> 1050 | AM18: ='2025 RNCR'!L14 -> 1050
B19: ='2025 RNCR'!A15 -> 9019 | C19: ='2025 RNCR'!C15 -> Botanica Blvd | D19: ='2025 RNCR'!D15 -> US 192-441 | E19: ='2025 RNCR'!E15 -> Crispin Cir | H19: =IF('2025 RNCR'!F15="U","D",IF('2025 RNCR'!F15="RU","C",IF('2025 RNCR'!F15="T","C","-"))) -> D | J19: ='2025 RNCR'!G15 -> Collector | K19: ='2025 RNCR'!H15 -> C3R | N19: ='2025 RNCR'!Z15 -> 1670 | R19: ='2025 RNCR'!Q15 -> 4543 | AE19: ='2025 RNCR'!R15 -> 248 | AF19: ='2025 RNCR'!S15 -> 121 | AG19: ='2025 RNCR'!AA15 -> 0.15 | AH19: ='2025 RNCR'!Y15 -> C | AJ19: ='2025 RNCR'!I15 -> 0 | AK19: ='2025 RNCR'!J15 -> 1530 | AL19: ='2025 RNCR'!K15 -> 1670 | AM19: ='2025 RNCR'!L15 -> 1670
B20: ='2025 RNCR'!A16 -> 2024 | C20: ='2025 RNCR'!C16 -> Broad St | D20: ='2025 RNCR'!D16 -> US 17/92 | E20: ='2025 RNCR'!E16 -> Old Tampa Hwy | H20: =IF('2025 RNCR'!F16="U","D",IF('2025 RNCR'!F16="RU","C",IF('2025 RNCR'!F16="T","C","-"))) -> D | J20: ='2025 RNCR'!G16 -> Collector | K20: ='2025 RNCR'!H16 -> C3C | N20: ='2025 RNCR'!Z16 -> 750 | R20: ='2025 RNCR'!Q16 -> 6334 | AE20: ='2025 RNCR'!R16 -> 249 | AF20: ='2025 RNCR'!S16 -> 286 | AG20: ='2025 RNCR'!AA16 -> 0.38 | AH20: ='2025 RNCR'!Y16 -> C | AJ20: ='2025 RNCR'!I16 -> 0 | AK20: ='2025 RNCR'!J16 -> 530 | AL20: ='2025 RNCR'!K16 -> 750 | AM20: ='2025 RNCR'!L16 -> 750
... B255: ='2025 RNCR'!A251 -> 1005 | C255: ='2025 RNCR'!C251 -> Zuni Rd | D255: ='2025 RNCR'!D251 -> Jack Brack Rd | E255: ='2025 RNCR'!E251 -> Cyrils Dr | H255: =IF('2025 RNCR'!F251="U","D",IF('2025 RNCR'!F251="RU","C",IF('2025 RNCR'!F251="T","C","-"))) -> D | J255: ='2025 RNCR'!G251 -> Collector | K255: ='2025 RNCR'!H251 -> C3R | N255: ='2025 RNCR'!Z251 -> 1000 | R255: ='2025 RNCR'!Q251 -> 3739 | AE255: ='2025 RNCR'!R251 -> 100 | AF255: ='2025 RNCR'!S251 -> 235 | AG255: ='2025 RNCR'!AA251 -> 0.24 | AH255: ='2025 RNCR'!Y251 -> C | AJ255: ='2025 RNCR'!I251 -> 0 | AK255: ='2025 RNCR'!J251 -> 870 | AL255: ='2025 RNCR'!K251 -> 1000 | AM255: ='2025 RNCR'!L251 -> 1000
